nohup: ignoring input
[2025-08-01 05:16:59 +0000] [59843] [INFO] Starting gunicorn 23.0.0
[2025-08-01 05:16:59 +0000] [59843] [INFO] Listening at: http://0.0.0.0:8000 (59843)
[2025-08-01 05:16:59 +0000] [59843] [INFO] Using worker: sync
[2025-08-01 05:16:59 +0000] [59852] [INFO] Booting worker with pid: 59852
[2025-08-01 13:08:58 +0000] [59852] [WARNING] Invalid request from ip=3.137.73.221: Invalid HTTP request line: 'SSH-2.0-Go'
[2025-08-01 22:40:39 +0000] [59852] [WARNING] Invalid request from ip=167.94.146.48: Invalid HTTP Version: (2, 0)
[2025-08-01 22:40:44 +0000] [59852] [WARNING] Invalid request from ip=167.94.146.48: Invalid HTTP Version: (2, 0)
[2025-08-02 01:19:13 +0000] [59852] [WARNING] Invalid request from ip=118.193.39.117: Invalid HTTP request line: ''
[2025-08-02 04:54:41 +0000] [59852] [WARNING] Invalid request from ip=206.168.34.40: Invalid HTTP Version: (2, 0)
[2025-08-02 04:55:13 +0000] [59852] [WARNING] Invalid request from ip=206.168.34.40: Invalid HTTP Version: (2, 0)
[2025-08-02 13:14:15 +0000] [59852] [WARNING] Invalid request from ip=3.132.23.201: Invalid HTTP request line: 'SSH-2.0-Go'
[2025-08-02 17:52:04 +0000] [59852] [WARNING] Invalid request from ip=167.94.145.97: Invalid HTTP Version: (2, 0)
[2025-08-02 17:52:11 +0000] [59852] [WARNING] Invalid request from ip=167.94.145.97: Invalid HTTP Version: (2, 0)
[2025-08-02 23:43:38 +0000] [59852] [WARNING] Invalid request from ip=167.94.145.103: Invalid HTTP Version: (2, 0)
[2025-08-02 23:43:45 +0000] [59852] [WARNING] Invalid request from ip=167.94.145.103: Invalid HTTP Version: (2, 0)
[2025-08-03 09:40:59 +0000] [59852] [WARNING] Invalid request from ip=206.168.34.57: Invalid HTTP Version: (2, 0)
[2025-08-03 12:29:17 +0000] [59852] [WARNING] Invalid request from ip=199.45.155.94: Invalid HTTP Version: (2, 0)
[2025-08-03 12:29:22 +0000] [59852] [WARNING] Invalid request from ip=199.45.155.94: Invalid HTTP Version: (2, 0)
[2025-08-03 15:30:58 +0000] [59852] [WARNING] Invalid request from ip=3.149.59.26: Invalid HTTP request line: 'SSH-2.0-Go'
[2025-08-04 06:39:04 +0000] [59852] [WARNING] Invalid request from ip=162.142.125.211: Invalid HTTP Version: (2, 0)
[2025-08-04 06:39:18 +0000] [59852] [WARNING] Invalid request from ip=162.142.125.211: Invalid HTTP Version: (2, 0)
[2025-08-04 06:39:58 +0000] [59843] [CRITICAL] WORKER TIMEOUT (pid:59852)
[2025-08-04 06:39:58 +0000] [59852] [ERROR] Error handling request (no URI read)
Traceback (most recent call last):
  File "/root/qr_checkout_latest/venv/lib/python3.13/site-packages/gunicorn/workers/sync.py", line 133, in handle
    req = next(parser)
  File "/root/qr_checkout_latest/venv/lib/python3.13/site-packages/gunicorn/http/parser.py", line 41, in __next__
    self.mesg = self.mesg_class(self.cfg, self.unreader, self.source_addr, self.req_count)
                ~~~~~~~~~~~~~~~^^^^^^^^^^^^^^^^^^^^^^^^^^^^^^^^^^^^^^^^^^^^^^^^^^^^^^^^^^^
  File "/root/qr_checkout_latest/venv/lib/python3.13/site-packages/gunicorn/http/message.py", line 259, in __init__
    super().__init__(cfg, unreader, peer_addr)
    ~~~~~~~~~~~~~~~~^^^^^^^^^^^^^^^^^^^^^^^^^^
  File "/root/qr_checkout_latest/venv/lib/python3.13/site-packages/gunicorn/http/message.py", line 60, in __init__
    unused = self.parse(self.unreader)
  File "/root/qr_checkout_latest/venv/lib/python3.13/site-packages/gunicorn/http/message.py", line 274, in parse
    line, rbuf = self.read_line(unreader, buf, self.limit_request_line)
                 ~~~~~~~~~~~~~~^^^^^^^^^^^^^^^^^^^^^^^^^^^^^^^^^^^^^^^^
  File "/root/qr_checkout_latest/venv/lib/python3.13/site-packages/gunicorn/http/message.py", line 326, in read_line
    self.get_data(unreader, buf)
    ~~~~~~~~~~~~~^^^^^^^^^^^^^^^
  File "/root/qr_checkout_latest/venv/lib/python3.13/site-packages/gunicorn/http/message.py", line 262, in get_data
    data = unreader.read()
  File "/root/qr_checkout_latest/venv/lib/python3.13/site-packages/gunicorn/http/unreader.py", line 36, in read
    d = self.chunk()
  File "/root/qr_checkout_latest/venv/lib/python3.13/site-packages/gunicorn/http/unreader.py", line 63, in chunk
    return self.sock.recv(self.mxchunk)
           ~~~~~~~~~~~~~~^^^^^^^^^^^^^^
  File "/root/qr_checkout_latest/venv/lib/python3.13/site-packages/gunicorn/workers/base.py", line 204, in handle_abort
    sys.exit(1)
    ~~~~~~~~^^^
SystemExit: 1
[2025-08-04 06:39:58 +0000] [59852] [INFO] Worker exiting (pid: 59852)
SUCCESS ROUTE HIT
Ticket: Test
Price: 10
SUCCESS ROUTE HIT
Ticket: General Admission (21 )
Price: 18.5
SUCCESS ROUTE HIT
Ticket: General Admission (21 )
Price: 18.5
SUCCESS ROUTE HIT
Ticket: General Admission (18 )
Price: 23.5
SUCCESS ROUTE HIT
Ticket: General Admission (18 )
Price: 23.5
SUCCESS ROUTE HIT
Ticket: General Admission (18 )
Price: 23.5
SUCCESS ROUTE HIT
Ticket: General Admission (18 )
Price: 23.5
SUCCESS ROUTE HIT
Ticket: General Admission (21 )
Price: 18.5
SUCCESS ROUTE HIT
Ticket: General Admission (21 )
Price: 18.5
SUCCESS ROUTE HIT
Ticket: General Admission (18 )
Price: 23.5
SUCCESS ROUTE HIT
Ticket: General Admission (21 )
Price: 18.5
SUCCESS ROUTE HIT
Ticket: General Admission (18 )
Price: 23.5
SUCCESS ROUTE HIT
Ticket: General Admission (18 )
Price: 23.5
SUCCESS ROUTE HIT
Ticket: General Admission (18 )
Price: 23.5
SUCCESS ROUTE HIT
Ticket: General Admission (21 )
Price: 18.5
SUCCESS ROUTE HIT
Ticket: General Admission (18 )
Price: 23.5
SUCCESS ROUTE HIT
Ticket: General Admission (18 )
Price: 23.5
SUCCESS ROUTE HIT
Ticket: General Admission (18 )
Price: 23.5
SUCCESS ROUTE HIT
Ticket: General Admission (18 )
Price: 23.5
SUCCESS ROUTE HIT
Ticket: General Admission (21 )
Price: 18.5
SUCCESS ROUTE HIT
Ticket: General Admission (21 )
Price: 18.5
SUCCESS ROUTE HIT
Ticket: General Admission (21 )
Price: 18.5
SUCCESS ROUTE HIT
Ticket: General Admission (21 )
Price: 18.5
SUCCESS ROUTE HIT
Ticket: General Admission (21 )
Price: 18.5
SUCCESS ROUTE HIT
Ticket: General Admission (21 )
Price: 18.5
SUCCESS ROUTE HIT
Ticket: General Admission (18 )
Price: 23.5
SUCCESS ROUTE HIT
Ticket: General Admission (21 )
Price: 18.5
SUCCESS ROUTE HIT
Ticket: General Admission (21 )
Price: 18.5
SUCCESS ROUTE HIT
Ticket: General Admission (21 )
Price: 18.5
SUCCESS ROUTE HIT
Ticket: General Admission (21 )
Price: 18.5
SUCCESS ROUTE HIT
Ticket: General Admission (18 )
Price: 23.5
SUCCESS ROUTE HIT
Ticket: General Admission (21 )
Price: 18.5
SUCCESS ROUTE HIT
Ticket: General Admission (21 )
Price: 18.5
SUCCESS ROUTE HIT
Ticket: General Admission (21 )
Price: 18.5
SUCCESS ROUTE HIT
Ticket: General Admission (18 )
Price: 23.5
SUCCESS ROUTE HIT
Ticket: General Admission (18 )
Price: 23.5
SUCCESS ROUTE HIT
Ticket: General Admission (18 )
Price: 23.5
SUCCESS ROUTE HIT
Ticket: General Admission (18 )
Price: 23.5
SUCCESS ROUTE HIT
Ticket: General Admission (18 )
Price: 23.5
SUCCESS ROUTE HIT
Ticket: General Admission (18 )
Price: 23.5
SUCCESS ROUTE HIT
Ticket: General Admission (21 )
Price: 18.5
SUCCESS ROUTE HIT
Ticket: General Admission (21 )
Price: 18.5
SUCCESS ROUTE HIT
Ticket: General Admission (18 )
Price: 23.5
SUCCESS ROUTE HIT
Ticket: General Admission (21 )
Price: 18.5
SUCCESS ROUTE HIT
Ticket: General Admission (18 )
Price: 23.5
SUCCESS ROUTE HIT
Ticket: General Admission (18 )
Price: 23.5
SUCCESS ROUTE HIT
Ticket: General Admission (18 )
Price: 23.5
SUCCESS ROUTE HIT
Ticket: General Admission (18 )
Price: 23.5
SUCCESS ROUTE HIT
Ticket: General Admission (21 )
Price: 18.5
SUCCESS ROUTE HIT
Ticket: General Admission (18 )
Price: 23.5
SUCCESS ROUTE HIT
Ticket: General Admission (18 )
Price: 23.5
SUCCESS ROUTE HIT
Ticket: General Admission (18 )
Price: 23.5
SUCCESS ROUTE HIT
Ticket: General Admission (18 )
Price: 23.5
SUCCESS ROUTE HIT
Ticket: General Admission (18 )
Price: 23.5
SUCCESS ROUTE HIT
Ticket: General Admission (18 )
Price: 23.5
SUCCESS ROUTE HIT
Ticket: General Admission (18 )
Price: 23.5
SUCCESS ROUTE HIT
Ticket: General Admission (18 )
Price: 23.5
SUCCESS ROUTE HIT
Ticket: General Admission (21 )
Price: 18.5
SUCCESS ROUTE HIT
Ticket: General Admission (18 )
Price: 23.5
SUCCESS ROUTE HIT
Ticket: General Admission (18 )
Price: 23.5
SUCCESS ROUTE HIT
Ticket: General Admission (21 )
Price: 18.5
SUCCESS ROUTE HIT
Ticket: General Admission (18 )
Price: 23.5
SUCCESS ROUTE HIT
Ticket: General Admission (18 )
Price: 23.5
SUCCESS ROUTE HIT
Ticket: General Admission (18 )
Price: 23.5
SUCCESS ROUTE HIT
Ticket: General Admission (18 )
Price: 23.5
SUCCESS ROUTE HIT
Ticket: General Admission (18 )
Price: 23.5
SUCCESS ROUTE HIT
Ticket: General Admission (18 )
Price: 23.5
SUCCESS ROUTE HIT
Ticket: General Admission (18 )
Price: 23.5
SUCCESS ROUTE HIT
Ticket: General Admission (21 )
Price: 18.5
SUCCESS ROUTE HIT
Ticket: General Admission (21 )
Price: 18.5
SUCCESS ROUTE HIT
Ticket: General Admission (21 )
Price: 18.5
SUCCESS ROUTE HIT
Ticket: General Admission (18 )
Price: 23.5
SUCCESS ROUTE HIT
Ticket: General Admission (18 )
Price: 23.5
SUCCESS ROUTE HIT
Ticket: General Admission (18 )
Price: 23.5
SUCCESS ROUTE HIT
Ticket: General Admission (18 )
Price: 23.5
SUCCESS ROUTE HIT
Ticket: General Admission (21 )
Price: 18.5
SUCCESS ROUTE HIT
Ticket: General Admission (21 )
Price: 18.5
SUCCESS ROUTE HIT
Ticket: General Admission (21 )
Price: 18.5
SUCCESS ROUTE HIT
Ticket: General Admission (18 )
Price: 23.5
SUCCESS ROUTE HIT
Ticket: General Admission (21 )
Price: 18.5
SUCCESS ROUTE HIT
Ticket: General Admission (18 )
Price: 23.5
[2025-08-04 06:39:59 +0000] [108359] [INFO] Booting worker with pid: 108359
[2025-08-04 14:25:52 +0000] [108359] [WARNING] Invalid request from ip=3.130.96.91: Invalid HTTP request line: 'SSH-2.0-Go'
[2025-08-05 06:55:48 +0000] [108359] [WARNING] Invalid request from ip=206.168.34.80: Invalid HTTP Version: (2, 0)
[2025-08-05 06:56:10 +0000] [108359] [WARNING] Invalid request from ip=206.168.34.80: Invalid HTTP Version: (2, 0)
[2025-08-05 07:48:29 +0000] [108359] [WARNING] Invalid request from ip=88.214.50.58: Invalid HTTP request line: '\x03\x00\x00/*Ã \x00\x00\x00\x00\x00Cookie: mstshash=Administr'
[2025-08-05 07:55:52 +0000] [108359] [WARNING] Invalid request from ip=88.214.50.70: Invalid HTTP request line: '\x03\x00\x00/*Ã \x00\x00\x00\x00\x00Cookie: mstshash=Administr'
[2025-08-05 07:56:35 +0000] [108359] [WARNING] Invalid request from ip=88.214.50.71: Invalid HTTP request line: '\x03\x00\x00/*Ã \x00\x00\x00\x00\x00Cookie: mstshash=Administr'
[2025-08-05 08:00:07 +0000] [108359] [WARNING] Invalid request from ip=165.154.129.43: Invalid HTTP request line: ''
[2025-08-05 08:02:23 +0000] [108359] [WARNING] Invalid request from ip=88.214.50.64: Invalid HTTP request line: '\x03\x00\x00/*Ã \x00\x00\x00\x00\x00Cookie: mstshash=Administr'
[2025-08-05 11:08:59 +0000] [108359] [WARNING] Invalid request from ip=88.214.50.58: Invalid HTTP request line: '\x03\x00\x00/*Ã \x00\x00\x00\x00\x00Cookie: mstshash=Administr'
[2025-08-05 11:13:03 +0000] [108359] [WARNING] Invalid request from ip=88.214.50.70: Invalid HTTP request line: '\x03\x00\x00/*Ã \x00\x00\x00\x00\x00Cookie: mstshash=Administr'
[2025-08-05 11:39:16 +0000] [108359] [WARNING] Invalid request from ip=88.214.50.64: Invalid HTTP request line: '\x03\x00\x00/*Ã \x00\x00\x00\x00\x00Cookie: mstshash=Administr'
[2025-08-05 11:41:29 +0000] [108359] [WARNING] Invalid request from ip=88.214.50.71: Invalid HTTP request line: '\x03\x00\x00/*Ã \x00\x00\x00\x00\x00Cookie: mstshash=Administr'
[2025-08-05 14:58:00 +0000] [108359] [WARNING] Invalid request from ip=88.214.50.58: Invalid HTTP request line: '\x03\x00\x00/*Ã \x00\x00\x00\x00\x00Cookie: mstshash=Administr'
[2025-08-05 15:15:52 +0000] [108359] [WARNING] Invalid request from ip=88.214.50.70: Invalid HTTP request line: '\x03\x00\x00/*Ã \x00\x00\x00\x00\x00Cookie: mstshash=Administr'
[2025-08-05 15:19:30 +0000] [108359] [WARNING] Invalid request from ip=3.131.215.38: Invalid HTTP request line: 'SSH-2.0-Go'
[2025-08-05 15:51:21 +0000] [108359] [WARNING] Invalid request from ip=88.214.50.64: Invalid HTTP request line: '\x03\x00\x00/*Ã \x00\x00\x00\x00\x00Cookie: mstshash=Administr'
[2025-08-05 15:53:33 +0000] [108359] [WARNING] Invalid request from ip=88.214.50.71: Invalid HTTP request line: '\x03\x00\x00/*Ã \x00\x00\x00\x00\x00Cookie: mstshash=Administr'
[2025-08-05 19:05:45 +0000] [108359] [WARNING] Invalid request from ip=88.214.50.58: Invalid HTTP request line: '\x03\x00\x00/*Ã \x00\x00\x00\x00\x00Cookie: mstshash=Administr'
[2025-08-05 19:13:55 +0000] [108359] [WARNING] Invalid request from ip=88.214.50.70: Invalid HTTP request line: '\x03\x00\x00/*Ã \x00\x00\x00\x00\x00Cookie: mstshash=Administr'
[2025-08-05 20:14:40 +0000] [108359] [WARNING] Invalid request from ip=88.214.50.71: Invalid HTTP request line: '\x03\x00\x00/*Ã \x00\x00\x00\x00\x00Cookie: mstshash=Administr'
[2025-08-05 20:46:26 +0000] [108359] [WARNING] Invalid request from ip=88.214.50.64: Invalid HTTP request line: '\x03\x00\x00/*Ã \x00\x00\x00\x00\x00Cookie: mstshash=Administr'
[2025-08-05 22:59:44 +0000] [108359] [WARNING] Invalid request from ip=88.214.50.58: Invalid HTTP request line: '\x03\x00\x00/*Ã \x00\x00\x00\x00\x00Cookie: mstshash=Administr'
[2025-08-05 23:26:12 +0000] [108359] [WARNING] Invalid request from ip=88.214.50.70: Invalid HTTP request line: '\x03\x00\x00/*Ã \x00\x00\x00\x00\x00Cookie: mstshash=Administr'
[2025-08-06 00:30:37 +0000] [108359] [WARNING] Invalid request from ip=88.214.50.71: Invalid HTTP request line: '\x03\x00\x00/*Ã \x00\x00\x00\x00\x00Cookie: mstshash=Administr'
[2025-08-06 00:50:47 +0000] [108359] [WARNING] Invalid request from ip=88.214.50.64: Invalid HTTP request line: '\x03\x00\x00/*Ã \x00\x00\x00\x00\x00Cookie: mstshash=Administr'
[2025-08-06 02:43:52 +0000] [108359] [WARNING] Invalid request from ip=88.214.50.58: Invalid HTTP request line: '\x03\x00\x00/*Ã \x00\x00\x00\x00\x00Cookie: mstshash=Administr'
[2025-08-06 03:17:35 +0000] [108359] [WARNING] Invalid request from ip=88.214.50.70: Invalid HTTP request line: '\x03\x00\x00/*Ã \x00\x00\x00\x00\x00Cookie: mstshash=Administr'
[2025-08-06 04:31:37 +0000] [108359] [WARNING] Invalid request from ip=88.214.50.71: Invalid HTTP request line: '\x03\x00\x00/*Ã \x00\x00\x00\x00\x00Cookie: mstshash=Administr'
[2025-08-06 04:40:37 +0000] [108359] [WARNING] Invalid request from ip=88.214.50.64: Invalid HTTP request line: '\x03\x00\x00/*Ã \x00\x00\x00\x00\x00Cookie: mstshash=Administr'
[2025-08-06 07:55:57 +0000] [108359] [WARNING] Invalid request from ip=167.94.138.122: Invalid HTTP Version: (2, 0)
[2025-08-06 07:56:54 +0000] [108359] [WARNING] Invalid request from ip=167.94.138.122: Invalid HTTP Version: (2, 0)
[2025-08-06 07:58:36 +0000] [59843] [CRITICAL] WORKER TIMEOUT (pid:108359)
[2025-08-06 07:58:36 +0000] [108359] [ERROR] Error handling request (no URI read)
Traceback (most recent call last):
  File "/root/qr_checkout_latest/venv/lib/python3.13/site-packages/gunicorn/workers/sync.py", line 133, in handle
    req = next(parser)
  File "/root/qr_checkout_latest/venv/lib/python3.13/site-packages/gunicorn/http/parser.py", line 41, in __next__
    self.mesg = self.mesg_class(self.cfg, self.unreader, self.source_addr, self.req_count)
                ~~~~~~~~~~~~~~~^^^^^^^^^^^^^^^^^^^^^^^^^^^^^^^^^^^^^^^^^^^^^^^^^^^^^^^^^^^
  File "/root/qr_checkout_latest/venv/lib/python3.13/site-packages/gunicorn/http/message.py", line 259, in __init__
    super().__init__(cfg, unreader, peer_addr)
    ~~~~~~~~~~~~~~~~^^^^^^^^^^^^^^^^^^^^^^^^^^
  File "/root/qr_checkout_latest/venv/lib/python3.13/site-packages/gunicorn/http/message.py", line 60, in __init__
    unused = self.parse(self.unreader)
  File "/root/qr_checkout_latest/venv/lib/python3.13/site-packages/gunicorn/http/message.py", line 274, in parse
    line, rbuf = self.read_line(unreader, buf, self.limit_request_line)
                 ~~~~~~~~~~~~~~^^^^^^^^^^^^^^^^^^^^^^^^^^^^^^^^^^^^^^^^
  File "/root/qr_checkout_latest/venv/lib/python3.13/site-packages/gunicorn/http/message.py", line 326, in read_line
    self.get_data(unreader, buf)
    ~~~~~~~~~~~~~^^^^^^^^^^^^^^^
  File "/root/qr_checkout_latest/venv/lib/python3.13/site-packages/gunicorn/http/message.py", line 262, in get_data
    data = unreader.read()
  File "/root/qr_checkout_latest/venv/lib/python3.13/site-packages/gunicorn/http/unreader.py", line 36, in read
    d = self.chunk()
  File "/root/qr_checkout_latest/venv/lib/python3.13/site-packages/gunicorn/http/unreader.py", line 63, in chunk
    return self.sock.recv(self.mxchunk)
           ~~~~~~~~~~~~~~^^^^^^^^^^^^^^
  File "/root/qr_checkout_latest/venv/lib/python3.13/site-packages/gunicorn/workers/base.py", line 204, in handle_abort
    sys.exit(1)
    ~~~~~~~~^^^
SystemExit: 1
[2025-08-06 07:58:36 +0000] [108359] [INFO] Worker exiting (pid: 108359)
SUCCESS ROUTE HIT
Ticket: General Admission (18 )
Price: 23.5
SUCCESS ROUTE HIT
Ticket: General Admission (18 )
Price: 23.5
[2025-08-06 07:58:36 +0000] [140962] [INFO] Booting worker with pid: 140962
[2025-08-06 08:05:00 +0000] [140962] [WARNING] Invalid request from ip=167.94.146.58: Invalid HTTP Version: (2, 0)
[2025-08-06 08:05:07 +0000] [140962] [WARNING] Invalid request from ip=167.94.146.58: Invalid HTTP Version: (2, 0)
[2025-08-06 10:50:23 +0000] [140962] [WARNING] Invalid request from ip=47.237.9.108: Invalid HTTP request line: ''
[2025-08-06 21:07:18 +0000] [140962] [WARNING] Invalid request from ip=3.143.33.63: Invalid HTTP request line: 'SSH-2.0-Go'
[2025-08-06 22:20:15 +0000] [140962] [WARNING] Invalid request from ip=3.137.73.221: Invalid HTTP request line: 'SSH-2.0-Go'
[2025-08-07 08:57:02 +0000] [140962] [WARNING] Invalid request from ip=206.168.34.93: Invalid HTTP Version: (2, 0)
[2025-08-07 08:57:24 +0000] [140962] [WARNING] Invalid request from ip=206.168.34.93: Invalid HTTP Version: (2, 0)
[2025-08-07 20:02:26 +0000] [140962] [WARNING] Invalid request from ip=3.132.23.201: Invalid HTTP request line: 'SSH-2.0-Go'
[2025-08-07 23:46:49 +0000] [59843] [CRITICAL] WORKER TIMEOUT (pid:140962)
[2025-08-07 23:46:49 +0000] [140962] [ERROR] Error handling request (no URI read)
Traceback (most recent call last):
  File "/root/qr_checkout_latest/venv/lib/python3.13/site-packages/gunicorn/workers/sync.py", line 133, in handle
    req = next(parser)
  File "/root/qr_checkout_latest/venv/lib/python3.13/site-packages/gunicorn/http/parser.py", line 41, in __next__
    self.mesg = self.mesg_class(self.cfg, self.unreader, self.source_addr, self.req_count)
                ~~~~~~~~~~~~~~~^^^^^^^^^^^^^^^^^^^^^^^^^^^^^^^^^^^^^^^^^^^^^^^^^^^^^^^^^^^
  File "/root/qr_checkout_latest/venv/lib/python3.13/site-packages/gunicorn/http/message.py", line 259, in __init__
    super().__init__(cfg, unreader, peer_addr)
    ~~~~~~~~~~~~~~~~^^^^^^^^^^^^^^^^^^^^^^^^^^
  File "/root/qr_checkout_latest/venv/lib/python3.13/site-packages/gunicorn/http/message.py", line 60, in __init__
    unused = self.parse(self.unreader)
  File "/root/qr_checkout_latest/venv/lib/python3.13/site-packages/gunicorn/http/message.py", line 271, in parse
    self.get_data(unreader, buf, stop=True)
    ~~~~~~~~~~~~~^^^^^^^^^^^^^^^^^^^^^^^^^^
  File "/root/qr_checkout_latest/venv/lib/python3.13/site-packages/gunicorn/http/message.py", line 262, in get_data
    data = unreader.read()
  File "/root/qr_checkout_latest/venv/lib/python3.13/site-packages/gunicorn/http/unreader.py", line 36, in read
    d = self.chunk()
  File "/root/qr_checkout_latest/venv/lib/python3.13/site-packages/gunicorn/http/unreader.py", line 63, in chunk
    return self.sock.recv(self.mxchunk)
           ~~~~~~~~~~~~~~^^^^^^^^^^^^^^
  File "/root/qr_checkout_latest/venv/lib/python3.13/site-packages/gunicorn/workers/base.py", line 204, in handle_abort
    sys.exit(1)
    ~~~~~~~~^^^
SystemExit: 1
[2025-08-07 23:46:49 +0000] [140962] [INFO] Worker exiting (pid: 140962)
SUCCESS ROUTE HIT
Ticket: General Admission (18 )
Price: 23.5
SUCCESS ROUTE HIT
Ticket: General Admission (18 )
Price: 23.5
SUCCESS ROUTE HIT
Ticket: General Admission (18 )
Price: 23.5
SUCCESS ROUTE HIT
Ticket: General Admission (18 )
Price: 23.5
[2025-08-07 23:46:50 +0000] [169485] [INFO] Booting worker with pid: 169485
[2025-08-08 00:28:42,828] ERROR in app: Exception on / [GET]
Traceback (most recent call last):
  File "/root/qr_checkout_latest/venv/lib/python3.13/site-packages/sqlalchemy/engine/base.py", line 1961, in _exec_single_context
    self.dialect.do_execute(
    ~~~~~~~~~~~~~~~~~~~~~~~^
        cursor, str_statement, effective_parameters, context
        ^^^^^^^^^^^^^^^^^^^^^^^^^^^^^^^^^^^^^^^^^^^^^^^^^^^^
    )
    ^
  File "/root/qr_checkout_latest/venv/lib/python3.13/site-packages/sqlalchemy/engine/default.py", line 944, in do_execute
    cursor.execute(statement, parameters)
    ~~~~~~~~~~~~~~^^^^^^^^^^^^^^^^^^^^^^^
sqlite3.OperationalError: no such table: ticket

The above exception was the direct cause of the following exception:

Traceback (most recent call last):
  File "/root/qr_checkout_latest/venv/lib/python3.13/site-packages/flask/app.py", line 1511, in wsgi_app
    response = self.full_dispatch_request()
  File "/root/qr_checkout_latest/venv/lib/python3.13/site-packages/flask/app.py", line 919, in full_dispatch_request
    rv = self.handle_user_exception(e)
  File "/root/qr_checkout_latest/venv/lib/python3.13/site-packages/flask/app.py", line 917, in full_dispatch_request
    rv = self.dispatch_request()
  File "/root/qr_checkout_latest/venv/lib/python3.13/site-packages/flask/app.py", line 902, in dispatch_request
    return self.ensure_sync(self.view_functions[rule.endpoint])(**view_args)  # type: ignore[no-any-return]
           ~~~~~~~~~~~~~~~~~~~~~~~~~~~~~~~~~~~~~~~~~~~~~~~~~~~~^^^^^^^^^^^^^
  File "/root/qr_checkout_latest/venv/lib/python3.13/site-packages/flask_login/utils.py", line 290, in decorated_view
    return current_app.ensure_sync(func)(*args, **kwargs)
           ~~~~~~~~~~~~~~~~~~~~~~~~~~~~~^^^^^^^^^^^^^^^^^
  File "/root/qr_checkout_latest/app.py", line 95, in index
    tickets = Ticket.query.filter_by(user_id=current_user.id).all()
  File "/root/qr_checkout_latest/venv/lib/python3.13/site-packages/sqlalchemy/orm/query.py", line 2704, in all
    return self._iter().all()  # type: ignore
           ~~~~~~~~~~^^
  File "/root/qr_checkout_latest/venv/lib/python3.13/site-packages/sqlalchemy/orm/query.py", line 2857, in _iter
    result: Union[ScalarResult[_T], Result[_T]] = self.session.execute(
                                                  ~~~~~~~~~~~~~~~~~~~~^
        statement,
        ^^^^^^^^^^
        params,
        ^^^^^^^
        execution_options={"_sa_orm_load_options": self.load_options},
        ^^^^^^^^^^^^^^^^^^^^^^^^^^^^^^^^^^^^^^^^^^^^^^^^^^^^^^^^^^^^^^
    )
    ^
  File "/root/qr_checkout_latest/venv/lib/python3.13/site-packages/sqlalchemy/orm/session.py", line 2365, in execute
    return self._execute_internal(
           ~~~~~~~~~~~~~~~~~~~~~~^
        statement,
        ^^^^^^^^^^
    ...<4 lines>...
        _add_event=_add_event,
        ^^^^^^^^^^^^^^^^^^^^^^
    )
    ^
  File "/root/qr_checkout_latest/venv/lib/python3.13/site-packages/sqlalchemy/orm/session.py", line 2251, in _execute_internal
    result: Result[Any] = compile_state_cls.orm_execute_statement(
                          ~~~~~~~~~~~~~~~~~~~~~~~~~~~~~~~~~~~~~~~^
        self,
        ^^^^^
    ...<4 lines>...
        conn,
        ^^^^^
    )
    ^
  File "/root/qr_checkout_latest/venv/lib/python3.13/site-packages/sqlalchemy/orm/context.py", line 306, in orm_execute_statement
    result = conn.execute(
        statement, params or {}, execution_options=execution_options
    )
  File "/root/qr_checkout_latest/venv/lib/python3.13/site-packages/sqlalchemy/engine/base.py", line 1413, in execute
    return meth(
        self,
        distilled_parameters,
        execution_options or NO_OPTIONS,
    )
  File "/root/qr_checkout_latest/venv/lib/python3.13/site-packages/sqlalchemy/sql/elements.py", line 526, in _execute_on_connection
    return connection._execute_clauseelement(
           ~~~~~~~~~~~~~~~~~~~~~~~~~~~~~~~~~^
        self, distilled_params, execution_options
        ^^^^^^^^^^^^^^^^^^^^^^^^^^^^^^^^^^^^^^^^^
    )
    ^
  File "/root/qr_checkout_latest/venv/lib/python3.13/site-packages/sqlalchemy/engine/base.py", line 1635, in _execute_clauseelement
    ret = self._execute_context(
        dialect,
    ...<8 lines>...
        cache_hit=cache_hit,
    )
  File "/root/qr_checkout_latest/venv/lib/python3.13/site-packages/sqlalchemy/engine/base.py", line 1840, in _execute_context
    return self._exec_single_context(
           ~~~~~~~~~~~~~~~~~~~~~~~~~^
        dialect, context, statement, parameters
        ^^^^^^^^^^^^^^^^^^^^^^^^^^^^^^^^^^^^^^^
    )
    ^
  File "/root/qr_checkout_latest/venv/lib/python3.13/site-packages/sqlalchemy/engine/base.py", line 1980, in _exec_single_context
    self._handle_dbapi_exception(
    ~~~~~~~~~~~~~~~~~~~~~~~~~~~~^
        e, str_statement, effective_parameters, cursor, context
        ^^^^^^^^^^^^^^^^^^^^^^^^^^^^^^^^^^^^^^^^^^^^^^^^^^^^^^^
    )
    ^
  File "/root/qr_checkout_latest/venv/lib/python3.13/site-packages/sqlalchemy/engine/base.py", line 2349, in _handle_dbapi_exception
    raise sqlalchemy_exception.with_traceback(exc_info[2]) from e
  File "/root/qr_checkout_latest/venv/lib/python3.13/site-packages/sqlalchemy/engine/base.py", line 1961, in _exec_single_context
    self.dialect.do_execute(
    ~~~~~~~~~~~~~~~~~~~~~~~^
        cursor, str_statement, effective_parameters, context
        ^^^^^^^^^^^^^^^^^^^^^^^^^^^^^^^^^^^^^^^^^^^^^^^^^^^^
    )
    ^
  File "/root/qr_checkout_latest/venv/lib/python3.13/site-packages/sqlalchemy/engine/default.py", line 944, in do_execute
    cursor.execute(statement, parameters)
    ~~~~~~~~~~~~~~^^^^^^^^^^^^^^^^^^^^^^^
sqlalchemy.exc.OperationalError: (sqlite3.OperationalError) no such table: ticket
[SQL: SELECT ticket.id AS ticket_id, ticket.name AS ticket_name, ticket.price AS ticket_price, ticket.user_id AS ticket_user_id 
FROM ticket 
WHERE ticket.user_id = ?]
[parameters: (7,)]
(Background on this error at: https://sqlalche.me/e/20/e3q8)
[2025-08-08 03:35:28,395] ERROR in app: Exception on / [GET]
Traceback (most recent call last):
  File "/root/qr_checkout_latest/venv/lib/python3.13/site-packages/sqlalchemy/engine/base.py", line 1961, in _exec_single_context
    self.dialect.do_execute(
    ~~~~~~~~~~~~~~~~~~~~~~~^
        cursor, str_statement, effective_parameters, context
        ^^^^^^^^^^^^^^^^^^^^^^^^^^^^^^^^^^^^^^^^^^^^^^^^^^^^
    )
    ^
  File "/root/qr_checkout_latest/venv/lib/python3.13/site-packages/sqlalchemy/engine/default.py", line 944, in do_execute
    cursor.execute(statement, parameters)
    ~~~~~~~~~~~~~~^^^^^^^^^^^^^^^^^^^^^^^
sqlite3.OperationalError: no such table: ticket

The above exception was the direct cause of the following exception:

Traceback (most recent call last):
  File "/root/qr_checkout_latest/venv/lib/python3.13/site-packages/flask/app.py", line 1511, in wsgi_app
    response = self.full_dispatch_request()
  File "/root/qr_checkout_latest/venv/lib/python3.13/site-packages/flask/app.py", line 919, in full_dispatch_request
    rv = self.handle_user_exception(e)
  File "/root/qr_checkout_latest/venv/lib/python3.13/site-packages/flask/app.py", line 917, in full_dispatch_request
    rv = self.dispatch_request()
  File "/root/qr_checkout_latest/venv/lib/python3.13/site-packages/flask/app.py", line 902, in dispatch_request
    return self.ensure_sync(self.view_functions[rule.endpoint])(**view_args)  # type: ignore[no-any-return]
           ~~~~~~~~~~~~~~~~~~~~~~~~~~~~~~~~~~~~~~~~~~~~~~~~~~~~^^^^^^^^^^^^^
  File "/root/qr_checkout_latest/venv/lib/python3.13/site-packages/flask_login/utils.py", line 290, in decorated_view
    return current_app.ensure_sync(func)(*args, **kwargs)
           ~~~~~~~~~~~~~~~~~~~~~~~~~~~~~^^^^^^^^^^^^^^^^^
  File "/root/qr_checkout_latest/app.py", line 95, in index
    # Pull this user's tickets
  File "/root/qr_checkout_latest/venv/lib/python3.13/site-packages/sqlalchemy/orm/query.py", line 2704, in all
    return self._iter().all()  # type: ignore
           ~~~~~~~~~~^^
  File "/root/qr_checkout_latest/venv/lib/python3.13/site-packages/sqlalchemy/orm/query.py", line 2857, in _iter
    result: Union[ScalarResult[_T], Result[_T]] = self.session.execute(
                                                  ~~~~~~~~~~~~~~~~~~~~^
        statement,
        ^^^^^^^^^^
        params,
        ^^^^^^^
        execution_options={"_sa_orm_load_options": self.load_options},
        ^^^^^^^^^^^^^^^^^^^^^^^^^^^^^^^^^^^^^^^^^^^^^^^^^^^^^^^^^^^^^^
    )
    ^
  File "/root/qr_checkout_latest/venv/lib/python3.13/site-packages/sqlalchemy/orm/session.py", line 2365, in execute
    return self._execute_internal(
           ~~~~~~~~~~~~~~~~~~~~~~^
        statement,
        ^^^^^^^^^^
    ...<4 lines>...
        _add_event=_add_event,
        ^^^^^^^^^^^^^^^^^^^^^^
    )
    ^
  File "/root/qr_checkout_latest/venv/lib/python3.13/site-packages/sqlalchemy/orm/session.py", line 2251, in _execute_internal
    result: Result[Any] = compile_state_cls.orm_execute_statement(
                          ~~~~~~~~~~~~~~~~~~~~~~~~~~~~~~~~~~~~~~~^
        self,
        ^^^^^
    ...<4 lines>...
        conn,
        ^^^^^
    )
    ^
  File "/root/qr_checkout_latest/venv/lib/python3.13/site-packages/sqlalchemy/orm/context.py", line 306, in orm_execute_statement
    result = conn.execute(
        statement, params or {}, execution_options=execution_options
    )
  File "/root/qr_checkout_latest/venv/lib/python3.13/site-packages/sqlalchemy/engine/base.py", line 1413, in execute
    return meth(
        self,
        distilled_parameters,
        execution_options or NO_OPTIONS,
    )
  File "/root/qr_checkout_latest/venv/lib/python3.13/site-packages/sqlalchemy/sql/elements.py", line 526, in _execute_on_connection
    return connection._execute_clauseelement(
           ~~~~~~~~~~~~~~~~~~~~~~~~~~~~~~~~~^
        self, distilled_params, execution_options
        ^^^^^^^^^^^^^^^^^^^^^^^^^^^^^^^^^^^^^^^^^
    )
    ^
  File "/root/qr_checkout_latest/venv/lib/python3.13/site-packages/sqlalchemy/engine/base.py", line 1635, in _execute_clauseelement
    ret = self._execute_context(
        dialect,
    ...<8 lines>...
        cache_hit=cache_hit,
    )
  File "/root/qr_checkout_latest/venv/lib/python3.13/site-packages/sqlalchemy/engine/base.py", line 1840, in _execute_context
    return self._exec_single_context(
           ~~~~~~~~~~~~~~~~~~~~~~~~~^
        dialect, context, statement, parameters
        ^^^^^^^^^^^^^^^^^^^^^^^^^^^^^^^^^^^^^^^
    )
    ^
  File "/root/qr_checkout_latest/venv/lib/python3.13/site-packages/sqlalchemy/engine/base.py", line 1980, in _exec_single_context
    self._handle_dbapi_exception(
    ~~~~~~~~~~~~~~~~~~~~~~~~~~~~^
        e, str_statement, effective_parameters, cursor, context
        ^^^^^^^^^^^^^^^^^^^^^^^^^^^^^^^^^^^^^^^^^^^^^^^^^^^^^^^
    )
    ^
  File "/root/qr_checkout_latest/venv/lib/python3.13/site-packages/sqlalchemy/engine/base.py", line 2349, in _handle_dbapi_exception
    raise sqlalchemy_exception.with_traceback(exc_info[2]) from e
  File "/root/qr_checkout_latest/venv/lib/python3.13/site-packages/sqlalchemy/engine/base.py", line 1961, in _exec_single_context
    self.dialect.do_execute(
    ~~~~~~~~~~~~~~~~~~~~~~~^
        cursor, str_statement, effective_parameters, context
        ^^^^^^^^^^^^^^^^^^^^^^^^^^^^^^^^^^^^^^^^^^^^^^^^^^^^
    )
    ^
  File "/root/qr_checkout_latest/venv/lib/python3.13/site-packages/sqlalchemy/engine/default.py", line 944, in do_execute
    cursor.execute(statement, parameters)
    ~~~~~~~~~~~~~~^^^^^^^^^^^^^^^^^^^^^^^
sqlalchemy.exc.OperationalError: (sqlite3.OperationalError) no such table: ticket
[SQL: SELECT ticket.id AS ticket_id, ticket.name AS ticket_name, ticket.price AS ticket_price, ticket.user_id AS ticket_user_id 
FROM ticket 
WHERE ticket.user_id = ?]
[parameters: (1,)]
(Background on this error at: https://sqlalche.me/e/20/e3q8)
[2025-08-08 03:35:30,037] ERROR in app: Exception on / [GET]
Traceback (most recent call last):
  File "/root/qr_checkout_latest/venv/lib/python3.13/site-packages/sqlalchemy/engine/base.py", line 1961, in _exec_single_context
    self.dialect.do_execute(
    ~~~~~~~~~~~~~~~~~~~~~~~^
        cursor, str_statement, effective_parameters, context
        ^^^^^^^^^^^^^^^^^^^^^^^^^^^^^^^^^^^^^^^^^^^^^^^^^^^^
    )
    ^
  File "/root/qr_checkout_latest/venv/lib/python3.13/site-packages/sqlalchemy/engine/default.py", line 944, in do_execute
    cursor.execute(statement, parameters)
    ~~~~~~~~~~~~~~^^^^^^^^^^^^^^^^^^^^^^^
sqlite3.OperationalError: no such table: ticket

The above exception was the direct cause of the following exception:

Traceback (most recent call last):
  File "/root/qr_checkout_latest/venv/lib/python3.13/site-packages/flask/app.py", line 1511, in wsgi_app
    response = self.full_dispatch_request()
  File "/root/qr_checkout_latest/venv/lib/python3.13/site-packages/flask/app.py", line 919, in full_dispatch_request
    rv = self.handle_user_exception(e)
  File "/root/qr_checkout_latest/venv/lib/python3.13/site-packages/flask/app.py", line 917, in full_dispatch_request
    rv = self.dispatch_request()
  File "/root/qr_checkout_latest/venv/lib/python3.13/site-packages/flask/app.py", line 902, in dispatch_request
    return self.ensure_sync(self.view_functions[rule.endpoint])(**view_args)  # type: ignore[no-any-return]
           ~~~~~~~~~~~~~~~~~~~~~~~~~~~~~~~~~~~~~~~~~~~~~~~~~~~~^^^^^^^^^^^^^
  File "/root/qr_checkout_latest/venv/lib/python3.13/site-packages/flask_login/utils.py", line 290, in decorated_view
    return current_app.ensure_sync(func)(*args, **kwargs)
           ~~~~~~~~~~~~~~~~~~~~~~~~~~~~~^^^^^^^^^^^^^^^^^
  File "/root/qr_checkout_latest/app.py", line 95, in index
    # Pull this user's tickets
  File "/root/qr_checkout_latest/venv/lib/python3.13/site-packages/sqlalchemy/orm/query.py", line 2704, in all
    return self._iter().all()  # type: ignore
           ~~~~~~~~~~^^
  File "/root/qr_checkout_latest/venv/lib/python3.13/site-packages/sqlalchemy/orm/query.py", line 2857, in _iter
    result: Union[ScalarResult[_T], Result[_T]] = self.session.execute(
                                                  ~~~~~~~~~~~~~~~~~~~~^
        statement,
        ^^^^^^^^^^
        params,
        ^^^^^^^
        execution_options={"_sa_orm_load_options": self.load_options},
        ^^^^^^^^^^^^^^^^^^^^^^^^^^^^^^^^^^^^^^^^^^^^^^^^^^^^^^^^^^^^^^
    )
    ^
  File "/root/qr_checkout_latest/venv/lib/python3.13/site-packages/sqlalchemy/orm/session.py", line 2365, in execute
    return self._execute_internal(
           ~~~~~~~~~~~~~~~~~~~~~~^
        statement,
        ^^^^^^^^^^
    ...<4 lines>...
        _add_event=_add_event,
        ^^^^^^^^^^^^^^^^^^^^^^
    )
    ^
  File "/root/qr_checkout_latest/venv/lib/python3.13/site-packages/sqlalchemy/orm/session.py", line 2251, in _execute_internal
    result: Result[Any] = compile_state_cls.orm_execute_statement(
                          ~~~~~~~~~~~~~~~~~~~~~~~~~~~~~~~~~~~~~~~^
        self,
        ^^^^^
    ...<4 lines>...
        conn,
        ^^^^^
    )
    ^
  File "/root/qr_checkout_latest/venv/lib/python3.13/site-packages/sqlalchemy/orm/context.py", line 306, in orm_execute_statement
    result = conn.execute(
        statement, params or {}, execution_options=execution_options
    )
  File "/root/qr_checkout_latest/venv/lib/python3.13/site-packages/sqlalchemy/engine/base.py", line 1413, in execute
    return meth(
        self,
        distilled_parameters,
        execution_options or NO_OPTIONS,
    )
  File "/root/qr_checkout_latest/venv/lib/python3.13/site-packages/sqlalchemy/sql/elements.py", line 526, in _execute_on_connection
    return connection._execute_clauseelement(
           ~~~~~~~~~~~~~~~~~~~~~~~~~~~~~~~~~^
        self, distilled_params, execution_options
        ^^^^^^^^^^^^^^^^^^^^^^^^^^^^^^^^^^^^^^^^^
    )
    ^
  File "/root/qr_checkout_latest/venv/lib/python3.13/site-packages/sqlalchemy/engine/base.py", line 1635, in _execute_clauseelement
    ret = self._execute_context(
        dialect,
    ...<8 lines>...
        cache_hit=cache_hit,
    )
  File "/root/qr_checkout_latest/venv/lib/python3.13/site-packages/sqlalchemy/engine/base.py", line 1840, in _execute_context
    return self._exec_single_context(
           ~~~~~~~~~~~~~~~~~~~~~~~~~^
        dialect, context, statement, parameters
        ^^^^^^^^^^^^^^^^^^^^^^^^^^^^^^^^^^^^^^^
    )
    ^
  File "/root/qr_checkout_latest/venv/lib/python3.13/site-packages/sqlalchemy/engine/base.py", line 1980, in _exec_single_context
    self._handle_dbapi_exception(
    ~~~~~~~~~~~~~~~~~~~~~~~~~~~~^
        e, str_statement, effective_parameters, cursor, context
        ^^^^^^^^^^^^^^^^^^^^^^^^^^^^^^^^^^^^^^^^^^^^^^^^^^^^^^^
    )
    ^
  File "/root/qr_checkout_latest/venv/lib/python3.13/site-packages/sqlalchemy/engine/base.py", line 2349, in _handle_dbapi_exception
    raise sqlalchemy_exception.with_traceback(exc_info[2]) from e
  File "/root/qr_checkout_latest/venv/lib/python3.13/site-packages/sqlalchemy/engine/base.py", line 1961, in _exec_single_context
    self.dialect.do_execute(
    ~~~~~~~~~~~~~~~~~~~~~~~^
        cursor, str_statement, effective_parameters, context
        ^^^^^^^^^^^^^^^^^^^^^^^^^^^^^^^^^^^^^^^^^^^^^^^^^^^^
    )
    ^
  File "/root/qr_checkout_latest/venv/lib/python3.13/site-packages/sqlalchemy/engine/default.py", line 944, in do_execute
    cursor.execute(statement, parameters)
    ~~~~~~~~~~~~~~^^^^^^^^^^^^^^^^^^^^^^^
sqlalchemy.exc.OperationalError: (sqlite3.OperationalError) no such table: ticket
[SQL: SELECT ticket.id AS ticket_id, ticket.name AS ticket_name, ticket.price AS ticket_price, ticket.user_id AS ticket_user_id 
FROM ticket 
WHERE ticket.user_id = ?]
[parameters: (1,)]
(Background on this error at: https://sqlalche.me/e/20/e3q8)
[2025-08-08 03:35:30,561] ERROR in app: Exception on / [GET]
Traceback (most recent call last):
  File "/root/qr_checkout_latest/venv/lib/python3.13/site-packages/sqlalchemy/engine/base.py", line 1961, in _exec_single_context
    self.dialect.do_execute(
    ~~~~~~~~~~~~~~~~~~~~~~~^
        cursor, str_statement, effective_parameters, context
        ^^^^^^^^^^^^^^^^^^^^^^^^^^^^^^^^^^^^^^^^^^^^^^^^^^^^
    )
    ^
  File "/root/qr_checkout_latest/venv/lib/python3.13/site-packages/sqlalchemy/engine/default.py", line 944, in do_execute
    cursor.execute(statement, parameters)
    ~~~~~~~~~~~~~~^^^^^^^^^^^^^^^^^^^^^^^
sqlite3.OperationalError: no such table: ticket

The above exception was the direct cause of the following exception:

Traceback (most recent call last):
  File "/root/qr_checkout_latest/venv/lib/python3.13/site-packages/flask/app.py", line 1511, in wsgi_app
    response = self.full_dispatch_request()
  File "/root/qr_checkout_latest/venv/lib/python3.13/site-packages/flask/app.py", line 919, in full_dispatch_request
    rv = self.handle_user_exception(e)
  File "/root/qr_checkout_latest/venv/lib/python3.13/site-packages/flask/app.py", line 917, in full_dispatch_request
    rv = self.dispatch_request()
  File "/root/qr_checkout_latest/venv/lib/python3.13/site-packages/flask/app.py", line 902, in dispatch_request
    return self.ensure_sync(self.view_functions[rule.endpoint])(**view_args)  # type: ignore[no-any-return]
           ~~~~~~~~~~~~~~~~~~~~~~~~~~~~~~~~~~~~~~~~~~~~~~~~~~~~^^^^^^^^^^^^^
  File "/root/qr_checkout_latest/venv/lib/python3.13/site-packages/flask_login/utils.py", line 290, in decorated_view
    return current_app.ensure_sync(func)(*args, **kwargs)
           ~~~~~~~~~~~~~~~~~~~~~~~~~~~~~^^^^^^^^^^^^^^^^^
  File "/root/qr_checkout_latest/app.py", line 95, in index
    # Pull this user's tickets
  File "/root/qr_checkout_latest/venv/lib/python3.13/site-packages/sqlalchemy/orm/query.py", line 2704, in all
    return self._iter().all()  # type: ignore
           ~~~~~~~~~~^^
  File "/root/qr_checkout_latest/venv/lib/python3.13/site-packages/sqlalchemy/orm/query.py", line 2857, in _iter
    result: Union[ScalarResult[_T], Result[_T]] = self.session.execute(
                                                  ~~~~~~~~~~~~~~~~~~~~^
        statement,
        ^^^^^^^^^^
        params,
        ^^^^^^^
        execution_options={"_sa_orm_load_options": self.load_options},
        ^^^^^^^^^^^^^^^^^^^^^^^^^^^^^^^^^^^^^^^^^^^^^^^^^^^^^^^^^^^^^^
    )
    ^
  File "/root/qr_checkout_latest/venv/lib/python3.13/site-packages/sqlalchemy/orm/session.py", line 2365, in execute
    return self._execute_internal(
           ~~~~~~~~~~~~~~~~~~~~~~^
        statement,
        ^^^^^^^^^^
    ...<4 lines>...
        _add_event=_add_event,
        ^^^^^^^^^^^^^^^^^^^^^^
    )
    ^
  File "/root/qr_checkout_latest/venv/lib/python3.13/site-packages/sqlalchemy/orm/session.py", line 2251, in _execute_internal
    result: Result[Any] = compile_state_cls.orm_execute_statement(
                          ~~~~~~~~~~~~~~~~~~~~~~~~~~~~~~~~~~~~~~~^
        self,
        ^^^^^
    ...<4 lines>...
        conn,
        ^^^^^
    )
    ^
  File "/root/qr_checkout_latest/venv/lib/python3.13/site-packages/sqlalchemy/orm/context.py", line 306, in orm_execute_statement
    result = conn.execute(
        statement, params or {}, execution_options=execution_options
    )
  File "/root/qr_checkout_latest/venv/lib/python3.13/site-packages/sqlalchemy/engine/base.py", line 1413, in execute
    return meth(
        self,
        distilled_parameters,
        execution_options or NO_OPTIONS,
    )
  File "/root/qr_checkout_latest/venv/lib/python3.13/site-packages/sqlalchemy/sql/elements.py", line 526, in _execute_on_connection
    return connection._execute_clauseelement(
           ~~~~~~~~~~~~~~~~~~~~~~~~~~~~~~~~~^
        self, distilled_params, execution_options
        ^^^^^^^^^^^^^^^^^^^^^^^^^^^^^^^^^^^^^^^^^
    )
    ^
  File "/root/qr_checkout_latest/venv/lib/python3.13/site-packages/sqlalchemy/engine/base.py", line 1635, in _execute_clauseelement
    ret = self._execute_context(
        dialect,
    ...<8 lines>...
        cache_hit=cache_hit,
    )
  File "/root/qr_checkout_latest/venv/lib/python3.13/site-packages/sqlalchemy/engine/base.py", line 1840, in _execute_context
    return self._exec_single_context(
           ~~~~~~~~~~~~~~~~~~~~~~~~~^
        dialect, context, statement, parameters
        ^^^^^^^^^^^^^^^^^^^^^^^^^^^^^^^^^^^^^^^
    )
    ^
  File "/root/qr_checkout_latest/venv/lib/python3.13/site-packages/sqlalchemy/engine/base.py", line 1980, in _exec_single_context
    self._handle_dbapi_exception(
    ~~~~~~~~~~~~~~~~~~~~~~~~~~~~^
        e, str_statement, effective_parameters, cursor, context
        ^^^^^^^^^^^^^^^^^^^^^^^^^^^^^^^^^^^^^^^^^^^^^^^^^^^^^^^
    )
    ^
  File "/root/qr_checkout_latest/venv/lib/python3.13/site-packages/sqlalchemy/engine/base.py", line 2349, in _handle_dbapi_exception
    raise sqlalchemy_exception.with_traceback(exc_info[2]) from e
  File "/root/qr_checkout_latest/venv/lib/python3.13/site-packages/sqlalchemy/engine/base.py", line 1961, in _exec_single_context
    self.dialect.do_execute(
    ~~~~~~~~~~~~~~~~~~~~~~~^
        cursor, str_statement, effective_parameters, context
        ^^^^^^^^^^^^^^^^^^^^^^^^^^^^^^^^^^^^^^^^^^^^^^^^^^^^
    )
    ^
  File "/root/qr_checkout_latest/venv/lib/python3.13/site-packages/sqlalchemy/engine/default.py", line 944, in do_execute
    cursor.execute(statement, parameters)
    ~~~~~~~~~~~~~~^^^^^^^^^^^^^^^^^^^^^^^
sqlalchemy.exc.OperationalError: (sqlite3.OperationalError) no such table: ticket
[SQL: SELECT ticket.id AS ticket_id, ticket.name AS ticket_name, ticket.price AS ticket_price, ticket.user_id AS ticket_user_id 
FROM ticket 
WHERE ticket.user_id = ?]
[parameters: (1,)]
(Background on this error at: https://sqlalche.me/e/20/e3q8)
[2025-08-08 03:35:30,752] ERROR in app: Exception on / [GET]
Traceback (most recent call last):
  File "/root/qr_checkout_latest/venv/lib/python3.13/site-packages/sqlalchemy/engine/base.py", line 1961, in _exec_single_context
    self.dialect.do_execute(
    ~~~~~~~~~~~~~~~~~~~~~~~^
        cursor, str_statement, effective_parameters, context
        ^^^^^^^^^^^^^^^^^^^^^^^^^^^^^^^^^^^^^^^^^^^^^^^^^^^^
    )
    ^
  File "/root/qr_checkout_latest/venv/lib/python3.13/site-packages/sqlalchemy/engine/default.py", line 944, in do_execute
    cursor.execute(statement, parameters)
    ~~~~~~~~~~~~~~^^^^^^^^^^^^^^^^^^^^^^^
sqlite3.OperationalError: no such table: ticket

The above exception was the direct cause of the following exception:

Traceback (most recent call last):
  File "/root/qr_checkout_latest/venv/lib/python3.13/site-packages/flask/app.py", line 1511, in wsgi_app
    response = self.full_dispatch_request()
  File "/root/qr_checkout_latest/venv/lib/python3.13/site-packages/flask/app.py", line 919, in full_dispatch_request
    rv = self.handle_user_exception(e)
  File "/root/qr_checkout_latest/venv/lib/python3.13/site-packages/flask/app.py", line 917, in full_dispatch_request
    rv = self.dispatch_request()
  File "/root/qr_checkout_latest/venv/lib/python3.13/site-packages/flask/app.py", line 902, in dispatch_request
    return self.ensure_sync(self.view_functions[rule.endpoint])(**view_args)  # type: ignore[no-any-return]
           ~~~~~~~~~~~~~~~~~~~~~~~~~~~~~~~~~~~~~~~~~~~~~~~~~~~~^^^^^^^^^^^^^
  File "/root/qr_checkout_latest/venv/lib/python3.13/site-packages/flask_login/utils.py", line 290, in decorated_view
    return current_app.ensure_sync(func)(*args, **kwargs)
           ~~~~~~~~~~~~~~~~~~~~~~~~~~~~~^^^^^^^^^^^^^^^^^
  File "/root/qr_checkout_latest/app.py", line 95, in index
    # Pull this user's tickets
  File "/root/qr_checkout_latest/venv/lib/python3.13/site-packages/sqlalchemy/orm/query.py", line 2704, in all
    return self._iter().all()  # type: ignore
           ~~~~~~~~~~^^
  File "/root/qr_checkout_latest/venv/lib/python3.13/site-packages/sqlalchemy/orm/query.py", line 2857, in _iter
    result: Union[ScalarResult[_T], Result[_T]] = self.session.execute(
                                                  ~~~~~~~~~~~~~~~~~~~~^
        statement,
        ^^^^^^^^^^
        params,
        ^^^^^^^
        execution_options={"_sa_orm_load_options": self.load_options},
        ^^^^^^^^^^^^^^^^^^^^^^^^^^^^^^^^^^^^^^^^^^^^^^^^^^^^^^^^^^^^^^
    )
    ^
  File "/root/qr_checkout_latest/venv/lib/python3.13/site-packages/sqlalchemy/orm/session.py", line 2365, in execute
    return self._execute_internal(
           ~~~~~~~~~~~~~~~~~~~~~~^
        statement,
        ^^^^^^^^^^
    ...<4 lines>...
        _add_event=_add_event,
        ^^^^^^^^^^^^^^^^^^^^^^
    )
    ^
  File "/root/qr_checkout_latest/venv/lib/python3.13/site-packages/sqlalchemy/orm/session.py", line 2251, in _execute_internal
    result: Result[Any] = compile_state_cls.orm_execute_statement(
                          ~~~~~~~~~~~~~~~~~~~~~~~~~~~~~~~~~~~~~~~^
        self,
        ^^^^^
    ...<4 lines>...
        conn,
        ^^^^^
    )
    ^
  File "/root/qr_checkout_latest/venv/lib/python3.13/site-packages/sqlalchemy/orm/context.py", line 306, in orm_execute_statement
    result = conn.execute(
        statement, params or {}, execution_options=execution_options
    )
  File "/root/qr_checkout_latest/venv/lib/python3.13/site-packages/sqlalchemy/engine/base.py", line 1413, in execute
    return meth(
        self,
        distilled_parameters,
        execution_options or NO_OPTIONS,
    )
  File "/root/qr_checkout_latest/venv/lib/python3.13/site-packages/sqlalchemy/sql/elements.py", line 526, in _execute_on_connection
    return connection._execute_clauseelement(
           ~~~~~~~~~~~~~~~~~~~~~~~~~~~~~~~~~^
        self, distilled_params, execution_options
        ^^^^^^^^^^^^^^^^^^^^^^^^^^^^^^^^^^^^^^^^^
    )
    ^
  File "/root/qr_checkout_latest/venv/lib/python3.13/site-packages/sqlalchemy/engine/base.py", line 1635, in _execute_clauseelement
    ret = self._execute_context(
        dialect,
    ...<8 lines>...
        cache_hit=cache_hit,
    )
  File "/root/qr_checkout_latest/venv/lib/python3.13/site-packages/sqlalchemy/engine/base.py", line 1840, in _execute_context
    return self._exec_single_context(
           ~~~~~~~~~~~~~~~~~~~~~~~~~^
        dialect, context, statement, parameters
        ^^^^^^^^^^^^^^^^^^^^^^^^^^^^^^^^^^^^^^^
    )
    ^
  File "/root/qr_checkout_latest/venv/lib/python3.13/site-packages/sqlalchemy/engine/base.py", line 1980, in _exec_single_context
    self._handle_dbapi_exception(
    ~~~~~~~~~~~~~~~~~~~~~~~~~~~~^
        e, str_statement, effective_parameters, cursor, context
        ^^^^^^^^^^^^^^^^^^^^^^^^^^^^^^^^^^^^^^^^^^^^^^^^^^^^^^^
    )
    ^
  File "/root/qr_checkout_latest/venv/lib/python3.13/site-packages/sqlalchemy/engine/base.py", line 2349, in _handle_dbapi_exception
    raise sqlalchemy_exception.with_traceback(exc_info[2]) from e
  File "/root/qr_checkout_latest/venv/lib/python3.13/site-packages/sqlalchemy/engine/base.py", line 1961, in _exec_single_context
    self.dialect.do_execute(
    ~~~~~~~~~~~~~~~~~~~~~~~^
        cursor, str_statement, effective_parameters, context
        ^^^^^^^^^^^^^^^^^^^^^^^^^^^^^^^^^^^^^^^^^^^^^^^^^^^^
    )
    ^
  File "/root/qr_checkout_latest/venv/lib/python3.13/site-packages/sqlalchemy/engine/default.py", line 944, in do_execute
    cursor.execute(statement, parameters)
    ~~~~~~~~~~~~~~^^^^^^^^^^^^^^^^^^^^^^^
sqlalchemy.exc.OperationalError: (sqlite3.OperationalError) no such table: ticket
[SQL: SELECT ticket.id AS ticket_id, ticket.name AS ticket_name, ticket.price AS ticket_price, ticket.user_id AS ticket_user_id 
FROM ticket 
WHERE ticket.user_id = ?]
[parameters: (1,)]
(Background on this error at: https://sqlalche.me/e/20/e3q8)
[2025-08-08 03:35:30,928] ERROR in app: Exception on / [GET]
Traceback (most recent call last):
  File "/root/qr_checkout_latest/venv/lib/python3.13/site-packages/sqlalchemy/engine/base.py", line 1961, in _exec_single_context
    self.dialect.do_execute(
    ~~~~~~~~~~~~~~~~~~~~~~~^
        cursor, str_statement, effective_parameters, context
        ^^^^^^^^^^^^^^^^^^^^^^^^^^^^^^^^^^^^^^^^^^^^^^^^^^^^
    )
    ^
  File "/root/qr_checkout_latest/venv/lib/python3.13/site-packages/sqlalchemy/engine/default.py", line 944, in do_execute
    cursor.execute(statement, parameters)
    ~~~~~~~~~~~~~~^^^^^^^^^^^^^^^^^^^^^^^
sqlite3.OperationalError: no such table: ticket

The above exception was the direct cause of the following exception:

Traceback (most recent call last):
  File "/root/qr_checkout_latest/venv/lib/python3.13/site-packages/flask/app.py", line 1511, in wsgi_app
    response = self.full_dispatch_request()
  File "/root/qr_checkout_latest/venv/lib/python3.13/site-packages/flask/app.py", line 919, in full_dispatch_request
    rv = self.handle_user_exception(e)
  File "/root/qr_checkout_latest/venv/lib/python3.13/site-packages/flask/app.py", line 917, in full_dispatch_request
    rv = self.dispatch_request()
  File "/root/qr_checkout_latest/venv/lib/python3.13/site-packages/flask/app.py", line 902, in dispatch_request
    return self.ensure_sync(self.view_functions[rule.endpoint])(**view_args)  # type: ignore[no-any-return]
           ~~~~~~~~~~~~~~~~~~~~~~~~~~~~~~~~~~~~~~~~~~~~~~~~~~~~^^^^^^^^^^^^^
  File "/root/qr_checkout_latest/venv/lib/python3.13/site-packages/flask_login/utils.py", line 290, in decorated_view
    return current_app.ensure_sync(func)(*args, **kwargs)
           ~~~~~~~~~~~~~~~~~~~~~~~~~~~~~^^^^^^^^^^^^^^^^^
  File "/root/qr_checkout_latest/app.py", line 95, in index
    # Pull this user's tickets
  File "/root/qr_checkout_latest/venv/lib/python3.13/site-packages/sqlalchemy/orm/query.py", line 2704, in all
    return self._iter().all()  # type: ignore
           ~~~~~~~~~~^^
  File "/root/qr_checkout_latest/venv/lib/python3.13/site-packages/sqlalchemy/orm/query.py", line 2857, in _iter
    result: Union[ScalarResult[_T], Result[_T]] = self.session.execute(
                                                  ~~~~~~~~~~~~~~~~~~~~^
        statement,
        ^^^^^^^^^^
        params,
        ^^^^^^^
        execution_options={"_sa_orm_load_options": self.load_options},
        ^^^^^^^^^^^^^^^^^^^^^^^^^^^^^^^^^^^^^^^^^^^^^^^^^^^^^^^^^^^^^^
    )
    ^
  File "/root/qr_checkout_latest/venv/lib/python3.13/site-packages/sqlalchemy/orm/session.py", line 2365, in execute
    return self._execute_internal(
           ~~~~~~~~~~~~~~~~~~~~~~^
        statement,
        ^^^^^^^^^^
    ...<4 lines>...
        _add_event=_add_event,
        ^^^^^^^^^^^^^^^^^^^^^^
    )
    ^
  File "/root/qr_checkout_latest/venv/lib/python3.13/site-packages/sqlalchemy/orm/session.py", line 2251, in _execute_internal
    result: Result[Any] = compile_state_cls.orm_execute_statement(
                          ~~~~~~~~~~~~~~~~~~~~~~~~~~~~~~~~~~~~~~~^
        self,
        ^^^^^
    ...<4 lines>...
        conn,
        ^^^^^
    )
    ^
  File "/root/qr_checkout_latest/venv/lib/python3.13/site-packages/sqlalchemy/orm/context.py", line 306, in orm_execute_statement
    result = conn.execute(
        statement, params or {}, execution_options=execution_options
    )
  File "/root/qr_checkout_latest/venv/lib/python3.13/site-packages/sqlalchemy/engine/base.py", line 1413, in execute
    return meth(
        self,
        distilled_parameters,
        execution_options or NO_OPTIONS,
    )
  File "/root/qr_checkout_latest/venv/lib/python3.13/site-packages/sqlalchemy/sql/elements.py", line 526, in _execute_on_connection
    return connection._execute_clauseelement(
           ~~~~~~~~~~~~~~~~~~~~~~~~~~~~~~~~~^
        self, distilled_params, execution_options
        ^^^^^^^^^^^^^^^^^^^^^^^^^^^^^^^^^^^^^^^^^
    )
    ^
  File "/root/qr_checkout_latest/venv/lib/python3.13/site-packages/sqlalchemy/engine/base.py", line 1635, in _execute_clauseelement
    ret = self._execute_context(
        dialect,
    ...<8 lines>...
        cache_hit=cache_hit,
    )
  File "/root/qr_checkout_latest/venv/lib/python3.13/site-packages/sqlalchemy/engine/base.py", line 1840, in _execute_context
    return self._exec_single_context(
           ~~~~~~~~~~~~~~~~~~~~~~~~~^
        dialect, context, statement, parameters
        ^^^^^^^^^^^^^^^^^^^^^^^^^^^^^^^^^^^^^^^
    )
    ^
  File "/root/qr_checkout_latest/venv/lib/python3.13/site-packages/sqlalchemy/engine/base.py", line 1980, in _exec_single_context
    self._handle_dbapi_exception(
    ~~~~~~~~~~~~~~~~~~~~~~~~~~~~^
        e, str_statement, effective_parameters, cursor, context
        ^^^^^^^^^^^^^^^^^^^^^^^^^^^^^^^^^^^^^^^^^^^^^^^^^^^^^^^
    )
    ^
  File "/root/qr_checkout_latest/venv/lib/python3.13/site-packages/sqlalchemy/engine/base.py", line 2349, in _handle_dbapi_exception
    raise sqlalchemy_exception.with_traceback(exc_info[2]) from e
  File "/root/qr_checkout_latest/venv/lib/python3.13/site-packages/sqlalchemy/engine/base.py", line 1961, in _exec_single_context
    self.dialect.do_execute(
    ~~~~~~~~~~~~~~~~~~~~~~~^
        cursor, str_statement, effective_parameters, context
        ^^^^^^^^^^^^^^^^^^^^^^^^^^^^^^^^^^^^^^^^^^^^^^^^^^^^
    )
    ^
  File "/root/qr_checkout_latest/venv/lib/python3.13/site-packages/sqlalchemy/engine/default.py", line 944, in do_execute
    cursor.execute(statement, parameters)
    ~~~~~~~~~~~~~~^^^^^^^^^^^^^^^^^^^^^^^
sqlalchemy.exc.OperationalError: (sqlite3.OperationalError) no such table: ticket
[SQL: SELECT ticket.id AS ticket_id, ticket.name AS ticket_name, ticket.price AS ticket_price, ticket.user_id AS ticket_user_id 
FROM ticket 
WHERE ticket.user_id = ?]
[parameters: (1,)]
(Background on this error at: https://sqlalche.me/e/20/e3q8)
[2025-08-08 03:35:31,104] ERROR in app: Exception on / [GET]
Traceback (most recent call last):
  File "/root/qr_checkout_latest/venv/lib/python3.13/site-packages/sqlalchemy/engine/base.py", line 1961, in _exec_single_context
    self.dialect.do_execute(
    ~~~~~~~~~~~~~~~~~~~~~~~^
        cursor, str_statement, effective_parameters, context
        ^^^^^^^^^^^^^^^^^^^^^^^^^^^^^^^^^^^^^^^^^^^^^^^^^^^^
    )
    ^
  File "/root/qr_checkout_latest/venv/lib/python3.13/site-packages/sqlalchemy/engine/default.py", line 944, in do_execute
    cursor.execute(statement, parameters)
    ~~~~~~~~~~~~~~^^^^^^^^^^^^^^^^^^^^^^^
sqlite3.OperationalError: no such table: ticket

The above exception was the direct cause of the following exception:

Traceback (most recent call last):
  File "/root/qr_checkout_latest/venv/lib/python3.13/site-packages/flask/app.py", line 1511, in wsgi_app
    response = self.full_dispatch_request()
  File "/root/qr_checkout_latest/venv/lib/python3.13/site-packages/flask/app.py", line 919, in full_dispatch_request
    rv = self.handle_user_exception(e)
  File "/root/qr_checkout_latest/venv/lib/python3.13/site-packages/flask/app.py", line 917, in full_dispatch_request
    rv = self.dispatch_request()
  File "/root/qr_checkout_latest/venv/lib/python3.13/site-packages/flask/app.py", line 902, in dispatch_request
    return self.ensure_sync(self.view_functions[rule.endpoint])(**view_args)  # type: ignore[no-any-return]
           ~~~~~~~~~~~~~~~~~~~~~~~~~~~~~~~~~~~~~~~~~~~~~~~~~~~~^^^^^^^^^^^^^
  File "/root/qr_checkout_latest/venv/lib/python3.13/site-packages/flask_login/utils.py", line 290, in decorated_view
    return current_app.ensure_sync(func)(*args, **kwargs)
           ~~~~~~~~~~~~~~~~~~~~~~~~~~~~~^^^^^^^^^^^^^^^^^
  File "/root/qr_checkout_latest/app.py", line 95, in index
    # Pull this user's tickets
  File "/root/qr_checkout_latest/venv/lib/python3.13/site-packages/sqlalchemy/orm/query.py", line 2704, in all
    return self._iter().all()  # type: ignore
           ~~~~~~~~~~^^
  File "/root/qr_checkout_latest/venv/lib/python3.13/site-packages/sqlalchemy/orm/query.py", line 2857, in _iter
    result: Union[ScalarResult[_T], Result[_T]] = self.session.execute(
                                                  ~~~~~~~~~~~~~~~~~~~~^
        statement,
        ^^^^^^^^^^
        params,
        ^^^^^^^
        execution_options={"_sa_orm_load_options": self.load_options},
        ^^^^^^^^^^^^^^^^^^^^^^^^^^^^^^^^^^^^^^^^^^^^^^^^^^^^^^^^^^^^^^
    )
    ^
  File "/root/qr_checkout_latest/venv/lib/python3.13/site-packages/sqlalchemy/orm/session.py", line 2365, in execute
    return self._execute_internal(
           ~~~~~~~~~~~~~~~~~~~~~~^
        statement,
        ^^^^^^^^^^
    ...<4 lines>...
        _add_event=_add_event,
        ^^^^^^^^^^^^^^^^^^^^^^
    )
    ^
  File "/root/qr_checkout_latest/venv/lib/python3.13/site-packages/sqlalchemy/orm/session.py", line 2251, in _execute_internal
    result: Result[Any] = compile_state_cls.orm_execute_statement(
                          ~~~~~~~~~~~~~~~~~~~~~~~~~~~~~~~~~~~~~~~^
        self,
        ^^^^^
    ...<4 lines>...
        conn,
        ^^^^^
    )
    ^
  File "/root/qr_checkout_latest/venv/lib/python3.13/site-packages/sqlalchemy/orm/context.py", line 306, in orm_execute_statement
    result = conn.execute(
        statement, params or {}, execution_options=execution_options
    )
  File "/root/qr_checkout_latest/venv/lib/python3.13/site-packages/sqlalchemy/engine/base.py", line 1413, in execute
    return meth(
        self,
        distilled_parameters,
        execution_options or NO_OPTIONS,
    )
  File "/root/qr_checkout_latest/venv/lib/python3.13/site-packages/sqlalchemy/sql/elements.py", line 526, in _execute_on_connection
    return connection._execute_clauseelement(
           ~~~~~~~~~~~~~~~~~~~~~~~~~~~~~~~~~^
        self, distilled_params, execution_options
        ^^^^^^^^^^^^^^^^^^^^^^^^^^^^^^^^^^^^^^^^^
    )
    ^
  File "/root/qr_checkout_latest/venv/lib/python3.13/site-packages/sqlalchemy/engine/base.py", line 1635, in _execute_clauseelement
    ret = self._execute_context(
        dialect,
    ...<8 lines>...
        cache_hit=cache_hit,
    )
  File "/root/qr_checkout_latest/venv/lib/python3.13/site-packages/sqlalchemy/engine/base.py", line 1840, in _execute_context
    return self._exec_single_context(
           ~~~~~~~~~~~~~~~~~~~~~~~~~^
        dialect, context, statement, parameters
        ^^^^^^^^^^^^^^^^^^^^^^^^^^^^^^^^^^^^^^^
    )
    ^
  File "/root/qr_checkout_latest/venv/lib/python3.13/site-packages/sqlalchemy/engine/base.py", line 1980, in _exec_single_context
    self._handle_dbapi_exception(
    ~~~~~~~~~~~~~~~~~~~~~~~~~~~~^
        e, str_statement, effective_parameters, cursor, context
        ^^^^^^^^^^^^^^^^^^^^^^^^^^^^^^^^^^^^^^^^^^^^^^^^^^^^^^^
    )
    ^
  File "/root/qr_checkout_latest/venv/lib/python3.13/site-packages/sqlalchemy/engine/base.py", line 2349, in _handle_dbapi_exception
    raise sqlalchemy_exception.with_traceback(exc_info[2]) from e
  File "/root/qr_checkout_latest/venv/lib/python3.13/site-packages/sqlalchemy/engine/base.py", line 1961, in _exec_single_context
    self.dialect.do_execute(
    ~~~~~~~~~~~~~~~~~~~~~~~^
        cursor, str_statement, effective_parameters, context
        ^^^^^^^^^^^^^^^^^^^^^^^^^^^^^^^^^^^^^^^^^^^^^^^^^^^^
    )
    ^
  File "/root/qr_checkout_latest/venv/lib/python3.13/site-packages/sqlalchemy/engine/default.py", line 944, in do_execute
    cursor.execute(statement, parameters)
    ~~~~~~~~~~~~~~^^^^^^^^^^^^^^^^^^^^^^^
sqlalchemy.exc.OperationalError: (sqlite3.OperationalError) no such table: ticket
[SQL: SELECT ticket.id AS ticket_id, ticket.name AS ticket_name, ticket.price AS ticket_price, ticket.user_id AS ticket_user_id 
FROM ticket 
WHERE ticket.user_id = ?]
[parameters: (1,)]
(Background on this error at: https://sqlalche.me/e/20/e3q8)
[2025-08-08 03:35:31,272] ERROR in app: Exception on / [GET]
Traceback (most recent call last):
  File "/root/qr_checkout_latest/venv/lib/python3.13/site-packages/sqlalchemy/engine/base.py", line 1961, in _exec_single_context
    self.dialect.do_execute(
    ~~~~~~~~~~~~~~~~~~~~~~~^
        cursor, str_statement, effective_parameters, context
        ^^^^^^^^^^^^^^^^^^^^^^^^^^^^^^^^^^^^^^^^^^^^^^^^^^^^
    )
    ^
  File "/root/qr_checkout_latest/venv/lib/python3.13/site-packages/sqlalchemy/engine/default.py", line 944, in do_execute
    cursor.execute(statement, parameters)
    ~~~~~~~~~~~~~~^^^^^^^^^^^^^^^^^^^^^^^
sqlite3.OperationalError: no such table: ticket

The above exception was the direct cause of the following exception:

Traceback (most recent call last):
  File "/root/qr_checkout_latest/venv/lib/python3.13/site-packages/flask/app.py", line 1511, in wsgi_app
    response = self.full_dispatch_request()
  File "/root/qr_checkout_latest/venv/lib/python3.13/site-packages/flask/app.py", line 919, in full_dispatch_request
    rv = self.handle_user_exception(e)
  File "/root/qr_checkout_latest/venv/lib/python3.13/site-packages/flask/app.py", line 917, in full_dispatch_request
    rv = self.dispatch_request()
  File "/root/qr_checkout_latest/venv/lib/python3.13/site-packages/flask/app.py", line 902, in dispatch_request
    return self.ensure_sync(self.view_functions[rule.endpoint])(**view_args)  # type: ignore[no-any-return]
           ~~~~~~~~~~~~~~~~~~~~~~~~~~~~~~~~~~~~~~~~~~~~~~~~~~~~^^^^^^^^^^^^^
  File "/root/qr_checkout_latest/venv/lib/python3.13/site-packages/flask_login/utils.py", line 290, in decorated_view
    return current_app.ensure_sync(func)(*args, **kwargs)
           ~~~~~~~~~~~~~~~~~~~~~~~~~~~~~^^^^^^^^^^^^^^^^^
  File "/root/qr_checkout_latest/app.py", line 95, in index
    # Pull this user's tickets
  File "/root/qr_checkout_latest/venv/lib/python3.13/site-packages/sqlalchemy/orm/query.py", line 2704, in all
    return self._iter().all()  # type: ignore
           ~~~~~~~~~~^^
  File "/root/qr_checkout_latest/venv/lib/python3.13/site-packages/sqlalchemy/orm/query.py", line 2857, in _iter
    result: Union[ScalarResult[_T], Result[_T]] = self.session.execute(
                                                  ~~~~~~~~~~~~~~~~~~~~^
        statement,
        ^^^^^^^^^^
        params,
        ^^^^^^^
        execution_options={"_sa_orm_load_options": self.load_options},
        ^^^^^^^^^^^^^^^^^^^^^^^^^^^^^^^^^^^^^^^^^^^^^^^^^^^^^^^^^^^^^^
    )
    ^
  File "/root/qr_checkout_latest/venv/lib/python3.13/site-packages/sqlalchemy/orm/session.py", line 2365, in execute
    return self._execute_internal(
           ~~~~~~~~~~~~~~~~~~~~~~^
        statement,
        ^^^^^^^^^^
    ...<4 lines>...
        _add_event=_add_event,
        ^^^^^^^^^^^^^^^^^^^^^^
    )
    ^
  File "/root/qr_checkout_latest/venv/lib/python3.13/site-packages/sqlalchemy/orm/session.py", line 2251, in _execute_internal
    result: Result[Any] = compile_state_cls.orm_execute_statement(
                          ~~~~~~~~~~~~~~~~~~~~~~~~~~~~~~~~~~~~~~~^
        self,
        ^^^^^
    ...<4 lines>...
        conn,
        ^^^^^
    )
    ^
  File "/root/qr_checkout_latest/venv/lib/python3.13/site-packages/sqlalchemy/orm/context.py", line 306, in orm_execute_statement
    result = conn.execute(
        statement, params or {}, execution_options=execution_options
    )
  File "/root/qr_checkout_latest/venv/lib/python3.13/site-packages/sqlalchemy/engine/base.py", line 1413, in execute
    return meth(
        self,
        distilled_parameters,
        execution_options or NO_OPTIONS,
    )
  File "/root/qr_checkout_latest/venv/lib/python3.13/site-packages/sqlalchemy/sql/elements.py", line 526, in _execute_on_connection
    return connection._execute_clauseelement(
           ~~~~~~~~~~~~~~~~~~~~~~~~~~~~~~~~~^
        self, distilled_params, execution_options
        ^^^^^^^^^^^^^^^^^^^^^^^^^^^^^^^^^^^^^^^^^
    )
    ^
  File "/root/qr_checkout_latest/venv/lib/python3.13/site-packages/sqlalchemy/engine/base.py", line 1635, in _execute_clauseelement
    ret = self._execute_context(
        dialect,
    ...<8 lines>...
        cache_hit=cache_hit,
    )
  File "/root/qr_checkout_latest/venv/lib/python3.13/site-packages/sqlalchemy/engine/base.py", line 1840, in _execute_context
    return self._exec_single_context(
           ~~~~~~~~~~~~~~~~~~~~~~~~~^
        dialect, context, statement, parameters
        ^^^^^^^^^^^^^^^^^^^^^^^^^^^^^^^^^^^^^^^
    )
    ^
  File "/root/qr_checkout_latest/venv/lib/python3.13/site-packages/sqlalchemy/engine/base.py", line 1980, in _exec_single_context
    self._handle_dbapi_exception(
    ~~~~~~~~~~~~~~~~~~~~~~~~~~~~^
        e, str_statement, effective_parameters, cursor, context
        ^^^^^^^^^^^^^^^^^^^^^^^^^^^^^^^^^^^^^^^^^^^^^^^^^^^^^^^
    )
    ^
  File "/root/qr_checkout_latest/venv/lib/python3.13/site-packages/sqlalchemy/engine/base.py", line 2349, in _handle_dbapi_exception
    raise sqlalchemy_exception.with_traceback(exc_info[2]) from e
  File "/root/qr_checkout_latest/venv/lib/python3.13/site-packages/sqlalchemy/engine/base.py", line 1961, in _exec_single_context
    self.dialect.do_execute(
    ~~~~~~~~~~~~~~~~~~~~~~~^
        cursor, str_statement, effective_parameters, context
        ^^^^^^^^^^^^^^^^^^^^^^^^^^^^^^^^^^^^^^^^^^^^^^^^^^^^
    )
    ^
  File "/root/qr_checkout_latest/venv/lib/python3.13/site-packages/sqlalchemy/engine/default.py", line 944, in do_execute
    cursor.execute(statement, parameters)
    ~~~~~~~~~~~~~~^^^^^^^^^^^^^^^^^^^^^^^
sqlalchemy.exc.OperationalError: (sqlite3.OperationalError) no such table: ticket
[SQL: SELECT ticket.id AS ticket_id, ticket.name AS ticket_name, ticket.price AS ticket_price, ticket.user_id AS ticket_user_id 
FROM ticket 
WHERE ticket.user_id = ?]
[parameters: (1,)]
(Background on this error at: https://sqlalche.me/e/20/e3q8)
[2025-08-08 03:35:31,456] ERROR in app: Exception on / [GET]
Traceback (most recent call last):
  File "/root/qr_checkout_latest/venv/lib/python3.13/site-packages/sqlalchemy/engine/base.py", line 1961, in _exec_single_context
    self.dialect.do_execute(
    ~~~~~~~~~~~~~~~~~~~~~~~^
        cursor, str_statement, effective_parameters, context
        ^^^^^^^^^^^^^^^^^^^^^^^^^^^^^^^^^^^^^^^^^^^^^^^^^^^^
    )
    ^
  File "/root/qr_checkout_latest/venv/lib/python3.13/site-packages/sqlalchemy/engine/default.py", line 944, in do_execute
    cursor.execute(statement, parameters)
    ~~~~~~~~~~~~~~^^^^^^^^^^^^^^^^^^^^^^^
sqlite3.OperationalError: no such table: ticket

The above exception was the direct cause of the following exception:

Traceback (most recent call last):
  File "/root/qr_checkout_latest/venv/lib/python3.13/site-packages/flask/app.py", line 1511, in wsgi_app
    response = self.full_dispatch_request()
  File "/root/qr_checkout_latest/venv/lib/python3.13/site-packages/flask/app.py", line 919, in full_dispatch_request
    rv = self.handle_user_exception(e)
  File "/root/qr_checkout_latest/venv/lib/python3.13/site-packages/flask/app.py", line 917, in full_dispatch_request
    rv = self.dispatch_request()
  File "/root/qr_checkout_latest/venv/lib/python3.13/site-packages/flask/app.py", line 902, in dispatch_request
    return self.ensure_sync(self.view_functions[rule.endpoint])(**view_args)  # type: ignore[no-any-return]
           ~~~~~~~~~~~~~~~~~~~~~~~~~~~~~~~~~~~~~~~~~~~~~~~~~~~~^^^^^^^^^^^^^
  File "/root/qr_checkout_latest/venv/lib/python3.13/site-packages/flask_login/utils.py", line 290, in decorated_view
    return current_app.ensure_sync(func)(*args, **kwargs)
           ~~~~~~~~~~~~~~~~~~~~~~~~~~~~~^^^^^^^^^^^^^^^^^
  File "/root/qr_checkout_latest/app.py", line 95, in index
    # Pull this user's tickets
  File "/root/qr_checkout_latest/venv/lib/python3.13/site-packages/sqlalchemy/orm/query.py", line 2704, in all
    return self._iter().all()  # type: ignore
           ~~~~~~~~~~^^
  File "/root/qr_checkout_latest/venv/lib/python3.13/site-packages/sqlalchemy/orm/query.py", line 2857, in _iter
    result: Union[ScalarResult[_T], Result[_T]] = self.session.execute(
                                                  ~~~~~~~~~~~~~~~~~~~~^
        statement,
        ^^^^^^^^^^
        params,
        ^^^^^^^
        execution_options={"_sa_orm_load_options": self.load_options},
        ^^^^^^^^^^^^^^^^^^^^^^^^^^^^^^^^^^^^^^^^^^^^^^^^^^^^^^^^^^^^^^
    )
    ^
  File "/root/qr_checkout_latest/venv/lib/python3.13/site-packages/sqlalchemy/orm/session.py", line 2365, in execute
    return self._execute_internal(
           ~~~~~~~~~~~~~~~~~~~~~~^
        statement,
        ^^^^^^^^^^
    ...<4 lines>...
        _add_event=_add_event,
        ^^^^^^^^^^^^^^^^^^^^^^
    )
    ^
  File "/root/qr_checkout_latest/venv/lib/python3.13/site-packages/sqlalchemy/orm/session.py", line 2251, in _execute_internal
    result: Result[Any] = compile_state_cls.orm_execute_statement(
                          ~~~~~~~~~~~~~~~~~~~~~~~~~~~~~~~~~~~~~~~^
        self,
        ^^^^^
    ...<4 lines>...
        conn,
        ^^^^^
    )
    ^
  File "/root/qr_checkout_latest/venv/lib/python3.13/site-packages/sqlalchemy/orm/context.py", line 306, in orm_execute_statement
    result = conn.execute(
        statement, params or {}, execution_options=execution_options
    )
  File "/root/qr_checkout_latest/venv/lib/python3.13/site-packages/sqlalchemy/engine/base.py", line 1413, in execute
    return meth(
        self,
        distilled_parameters,
        execution_options or NO_OPTIONS,
    )
  File "/root/qr_checkout_latest/venv/lib/python3.13/site-packages/sqlalchemy/sql/elements.py", line 526, in _execute_on_connection
    return connection._execute_clauseelement(
           ~~~~~~~~~~~~~~~~~~~~~~~~~~~~~~~~~^
        self, distilled_params, execution_options
        ^^^^^^^^^^^^^^^^^^^^^^^^^^^^^^^^^^^^^^^^^
    )
    ^
  File "/root/qr_checkout_latest/venv/lib/python3.13/site-packages/sqlalchemy/engine/base.py", line 1635, in _execute_clauseelement
    ret = self._execute_context(
        dialect,
    ...<8 lines>...
        cache_hit=cache_hit,
    )
  File "/root/qr_checkout_latest/venv/lib/python3.13/site-packages/sqlalchemy/engine/base.py", line 1840, in _execute_context
    return self._exec_single_context(
           ~~~~~~~~~~~~~~~~~~~~~~~~~^
        dialect, context, statement, parameters
        ^^^^^^^^^^^^^^^^^^^^^^^^^^^^^^^^^^^^^^^
    )
    ^
  File "/root/qr_checkout_latest/venv/lib/python3.13/site-packages/sqlalchemy/engine/base.py", line 1980, in _exec_single_context
    self._handle_dbapi_exception(
    ~~~~~~~~~~~~~~~~~~~~~~~~~~~~^
        e, str_statement, effective_parameters, cursor, context
        ^^^^^^^^^^^^^^^^^^^^^^^^^^^^^^^^^^^^^^^^^^^^^^^^^^^^^^^
    )
    ^
  File "/root/qr_checkout_latest/venv/lib/python3.13/site-packages/sqlalchemy/engine/base.py", line 2349, in _handle_dbapi_exception
    raise sqlalchemy_exception.with_traceback(exc_info[2]) from e
  File "/root/qr_checkout_latest/venv/lib/python3.13/site-packages/sqlalchemy/engine/base.py", line 1961, in _exec_single_context
    self.dialect.do_execute(
    ~~~~~~~~~~~~~~~~~~~~~~~^
        cursor, str_statement, effective_parameters, context
        ^^^^^^^^^^^^^^^^^^^^^^^^^^^^^^^^^^^^^^^^^^^^^^^^^^^^
    )
    ^
  File "/root/qr_checkout_latest/venv/lib/python3.13/site-packages/sqlalchemy/engine/default.py", line 944, in do_execute
    cursor.execute(statement, parameters)
    ~~~~~~~~~~~~~~^^^^^^^^^^^^^^^^^^^^^^^
sqlalchemy.exc.OperationalError: (sqlite3.OperationalError) no such table: ticket
[SQL: SELECT ticket.id AS ticket_id, ticket.name AS ticket_name, ticket.price AS ticket_price, ticket.user_id AS ticket_user_id 
FROM ticket 
WHERE ticket.user_id = ?]
[parameters: (1,)]
(Background on this error at: https://sqlalche.me/e/20/e3q8)
[2025-08-08 03:35:31,600] ERROR in app: Exception on / [GET]
Traceback (most recent call last):
  File "/root/qr_checkout_latest/venv/lib/python3.13/site-packages/sqlalchemy/engine/base.py", line 1961, in _exec_single_context
    self.dialect.do_execute(
    ~~~~~~~~~~~~~~~~~~~~~~~^
        cursor, str_statement, effective_parameters, context
        ^^^^^^^^^^^^^^^^^^^^^^^^^^^^^^^^^^^^^^^^^^^^^^^^^^^^
    )
    ^
  File "/root/qr_checkout_latest/venv/lib/python3.13/site-packages/sqlalchemy/engine/default.py", line 944, in do_execute
    cursor.execute(statement, parameters)
    ~~~~~~~~~~~~~~^^^^^^^^^^^^^^^^^^^^^^^
sqlite3.OperationalError: no such table: ticket

The above exception was the direct cause of the following exception:

Traceback (most recent call last):
  File "/root/qr_checkout_latest/venv/lib/python3.13/site-packages/flask/app.py", line 1511, in wsgi_app
    response = self.full_dispatch_request()
  File "/root/qr_checkout_latest/venv/lib/python3.13/site-packages/flask/app.py", line 919, in full_dispatch_request
    rv = self.handle_user_exception(e)
  File "/root/qr_checkout_latest/venv/lib/python3.13/site-packages/flask/app.py", line 917, in full_dispatch_request
    rv = self.dispatch_request()
  File "/root/qr_checkout_latest/venv/lib/python3.13/site-packages/flask/app.py", line 902, in dispatch_request
    return self.ensure_sync(self.view_functions[rule.endpoint])(**view_args)  # type: ignore[no-any-return]
           ~~~~~~~~~~~~~~~~~~~~~~~~~~~~~~~~~~~~~~~~~~~~~~~~~~~~^^^^^^^^^^^^^
  File "/root/qr_checkout_latest/venv/lib/python3.13/site-packages/flask_login/utils.py", line 290, in decorated_view
    return current_app.ensure_sync(func)(*args, **kwargs)
           ~~~~~~~~~~~~~~~~~~~~~~~~~~~~~^^^^^^^^^^^^^^^^^
  File "/root/qr_checkout_latest/app.py", line 95, in index
    # Pull this user's tickets
  File "/root/qr_checkout_latest/venv/lib/python3.13/site-packages/sqlalchemy/orm/query.py", line 2704, in all
    return self._iter().all()  # type: ignore
           ~~~~~~~~~~^^
  File "/root/qr_checkout_latest/venv/lib/python3.13/site-packages/sqlalchemy/orm/query.py", line 2857, in _iter
    result: Union[ScalarResult[_T], Result[_T]] = self.session.execute(
                                                  ~~~~~~~~~~~~~~~~~~~~^
        statement,
        ^^^^^^^^^^
        params,
        ^^^^^^^
        execution_options={"_sa_orm_load_options": self.load_options},
        ^^^^^^^^^^^^^^^^^^^^^^^^^^^^^^^^^^^^^^^^^^^^^^^^^^^^^^^^^^^^^^
    )
    ^
  File "/root/qr_checkout_latest/venv/lib/python3.13/site-packages/sqlalchemy/orm/session.py", line 2365, in execute
    return self._execute_internal(
           ~~~~~~~~~~~~~~~~~~~~~~^
        statement,
        ^^^^^^^^^^
    ...<4 lines>...
        _add_event=_add_event,
        ^^^^^^^^^^^^^^^^^^^^^^
    )
    ^
  File "/root/qr_checkout_latest/venv/lib/python3.13/site-packages/sqlalchemy/orm/session.py", line 2251, in _execute_internal
    result: Result[Any] = compile_state_cls.orm_execute_statement(
                          ~~~~~~~~~~~~~~~~~~~~~~~~~~~~~~~~~~~~~~~^
        self,
        ^^^^^
    ...<4 lines>...
        conn,
        ^^^^^
    )
    ^
  File "/root/qr_checkout_latest/venv/lib/python3.13/site-packages/sqlalchemy/orm/context.py", line 306, in orm_execute_statement
    result = conn.execute(
        statement, params or {}, execution_options=execution_options
    )
  File "/root/qr_checkout_latest/venv/lib/python3.13/site-packages/sqlalchemy/engine/base.py", line 1413, in execute
    return meth(
        self,
        distilled_parameters,
        execution_options or NO_OPTIONS,
    )
  File "/root/qr_checkout_latest/venv/lib/python3.13/site-packages/sqlalchemy/sql/elements.py", line 526, in _execute_on_connection
    return connection._execute_clauseelement(
           ~~~~~~~~~~~~~~~~~~~~~~~~~~~~~~~~~^
        self, distilled_params, execution_options
        ^^^^^^^^^^^^^^^^^^^^^^^^^^^^^^^^^^^^^^^^^
    )
    ^
  File "/root/qr_checkout_latest/venv/lib/python3.13/site-packages/sqlalchemy/engine/base.py", line 1635, in _execute_clauseelement
    ret = self._execute_context(
        dialect,
    ...<8 lines>...
        cache_hit=cache_hit,
    )
  File "/root/qr_checkout_latest/venv/lib/python3.13/site-packages/sqlalchemy/engine/base.py", line 1840, in _execute_context
    return self._exec_single_context(
           ~~~~~~~~~~~~~~~~~~~~~~~~~^
        dialect, context, statement, parameters
        ^^^^^^^^^^^^^^^^^^^^^^^^^^^^^^^^^^^^^^^
    )
    ^
  File "/root/qr_checkout_latest/venv/lib/python3.13/site-packages/sqlalchemy/engine/base.py", line 1980, in _exec_single_context
    self._handle_dbapi_exception(
    ~~~~~~~~~~~~~~~~~~~~~~~~~~~~^
        e, str_statement, effective_parameters, cursor, context
        ^^^^^^^^^^^^^^^^^^^^^^^^^^^^^^^^^^^^^^^^^^^^^^^^^^^^^^^
    )
    ^
  File "/root/qr_checkout_latest/venv/lib/python3.13/site-packages/sqlalchemy/engine/base.py", line 2349, in _handle_dbapi_exception
    raise sqlalchemy_exception.with_traceback(exc_info[2]) from e
  File "/root/qr_checkout_latest/venv/lib/python3.13/site-packages/sqlalchemy/engine/base.py", line 1961, in _exec_single_context
    self.dialect.do_execute(
    ~~~~~~~~~~~~~~~~~~~~~~~^
        cursor, str_statement, effective_parameters, context
        ^^^^^^^^^^^^^^^^^^^^^^^^^^^^^^^^^^^^^^^^^^^^^^^^^^^^
    )
    ^
  File "/root/qr_checkout_latest/venv/lib/python3.13/site-packages/sqlalchemy/engine/default.py", line 944, in do_execute
    cursor.execute(statement, parameters)
    ~~~~~~~~~~~~~~^^^^^^^^^^^^^^^^^^^^^^^
sqlalchemy.exc.OperationalError: (sqlite3.OperationalError) no such table: ticket
[SQL: SELECT ticket.id AS ticket_id, ticket.name AS ticket_name, ticket.price AS ticket_price, ticket.user_id AS ticket_user_id 
FROM ticket 
WHERE ticket.user_id = ?]
[parameters: (1,)]
(Background on this error at: https://sqlalche.me/e/20/e3q8)
[2025-08-08 03:35:31,792] ERROR in app: Exception on / [GET]
Traceback (most recent call last):
  File "/root/qr_checkout_latest/venv/lib/python3.13/site-packages/sqlalchemy/engine/base.py", line 1961, in _exec_single_context
    self.dialect.do_execute(
    ~~~~~~~~~~~~~~~~~~~~~~~^
        cursor, str_statement, effective_parameters, context
        ^^^^^^^^^^^^^^^^^^^^^^^^^^^^^^^^^^^^^^^^^^^^^^^^^^^^
    )
    ^
  File "/root/qr_checkout_latest/venv/lib/python3.13/site-packages/sqlalchemy/engine/default.py", line 944, in do_execute
    cursor.execute(statement, parameters)
    ~~~~~~~~~~~~~~^^^^^^^^^^^^^^^^^^^^^^^
sqlite3.OperationalError: no such table: ticket

The above exception was the direct cause of the following exception:

Traceback (most recent call last):
  File "/root/qr_checkout_latest/venv/lib/python3.13/site-packages/flask/app.py", line 1511, in wsgi_app
    response = self.full_dispatch_request()
  File "/root/qr_checkout_latest/venv/lib/python3.13/site-packages/flask/app.py", line 919, in full_dispatch_request
    rv = self.handle_user_exception(e)
  File "/root/qr_checkout_latest/venv/lib/python3.13/site-packages/flask/app.py", line 917, in full_dispatch_request
    rv = self.dispatch_request()
  File "/root/qr_checkout_latest/venv/lib/python3.13/site-packages/flask/app.py", line 902, in dispatch_request
    return self.ensure_sync(self.view_functions[rule.endpoint])(**view_args)  # type: ignore[no-any-return]
           ~~~~~~~~~~~~~~~~~~~~~~~~~~~~~~~~~~~~~~~~~~~~~~~~~~~~^^^^^^^^^^^^^
  File "/root/qr_checkout_latest/venv/lib/python3.13/site-packages/flask_login/utils.py", line 290, in decorated_view
    return current_app.ensure_sync(func)(*args, **kwargs)
           ~~~~~~~~~~~~~~~~~~~~~~~~~~~~~^^^^^^^^^^^^^^^^^
  File "/root/qr_checkout_latest/app.py", line 95, in index
    # Pull this user's tickets
  File "/root/qr_checkout_latest/venv/lib/python3.13/site-packages/sqlalchemy/orm/query.py", line 2704, in all
    return self._iter().all()  # type: ignore
           ~~~~~~~~~~^^
  File "/root/qr_checkout_latest/venv/lib/python3.13/site-packages/sqlalchemy/orm/query.py", line 2857, in _iter
    result: Union[ScalarResult[_T], Result[_T]] = self.session.execute(
                                                  ~~~~~~~~~~~~~~~~~~~~^
        statement,
        ^^^^^^^^^^
        params,
        ^^^^^^^
        execution_options={"_sa_orm_load_options": self.load_options},
        ^^^^^^^^^^^^^^^^^^^^^^^^^^^^^^^^^^^^^^^^^^^^^^^^^^^^^^^^^^^^^^
    )
    ^
  File "/root/qr_checkout_latest/venv/lib/python3.13/site-packages/sqlalchemy/orm/session.py", line 2365, in execute
    return self._execute_internal(
           ~~~~~~~~~~~~~~~~~~~~~~^
        statement,
        ^^^^^^^^^^
    ...<4 lines>...
        _add_event=_add_event,
        ^^^^^^^^^^^^^^^^^^^^^^
    )
    ^
  File "/root/qr_checkout_latest/venv/lib/python3.13/site-packages/sqlalchemy/orm/session.py", line 2251, in _execute_internal
    result: Result[Any] = compile_state_cls.orm_execute_statement(
                          ~~~~~~~~~~~~~~~~~~~~~~~~~~~~~~~~~~~~~~~^
        self,
        ^^^^^
    ...<4 lines>...
        conn,
        ^^^^^
    )
    ^
  File "/root/qr_checkout_latest/venv/lib/python3.13/site-packages/sqlalchemy/orm/context.py", line 306, in orm_execute_statement
    result = conn.execute(
        statement, params or {}, execution_options=execution_options
    )
  File "/root/qr_checkout_latest/venv/lib/python3.13/site-packages/sqlalchemy/engine/base.py", line 1413, in execute
    return meth(
        self,
        distilled_parameters,
        execution_options or NO_OPTIONS,
    )
  File "/root/qr_checkout_latest/venv/lib/python3.13/site-packages/sqlalchemy/sql/elements.py", line 526, in _execute_on_connection
    return connection._execute_clauseelement(
           ~~~~~~~~~~~~~~~~~~~~~~~~~~~~~~~~~^
        self, distilled_params, execution_options
        ^^^^^^^^^^^^^^^^^^^^^^^^^^^^^^^^^^^^^^^^^
    )
    ^
  File "/root/qr_checkout_latest/venv/lib/python3.13/site-packages/sqlalchemy/engine/base.py", line 1635, in _execute_clauseelement
    ret = self._execute_context(
        dialect,
    ...<8 lines>...
        cache_hit=cache_hit,
    )
  File "/root/qr_checkout_latest/venv/lib/python3.13/site-packages/sqlalchemy/engine/base.py", line 1840, in _execute_context
    return self._exec_single_context(
           ~~~~~~~~~~~~~~~~~~~~~~~~~^
        dialect, context, statement, parameters
        ^^^^^^^^^^^^^^^^^^^^^^^^^^^^^^^^^^^^^^^
    )
    ^
  File "/root/qr_checkout_latest/venv/lib/python3.13/site-packages/sqlalchemy/engine/base.py", line 1980, in _exec_single_context
    self._handle_dbapi_exception(
    ~~~~~~~~~~~~~~~~~~~~~~~~~~~~^
        e, str_statement, effective_parameters, cursor, context
        ^^^^^^^^^^^^^^^^^^^^^^^^^^^^^^^^^^^^^^^^^^^^^^^^^^^^^^^
    )
    ^
  File "/root/qr_checkout_latest/venv/lib/python3.13/site-packages/sqlalchemy/engine/base.py", line 2349, in _handle_dbapi_exception
    raise sqlalchemy_exception.with_traceback(exc_info[2]) from e
  File "/root/qr_checkout_latest/venv/lib/python3.13/site-packages/sqlalchemy/engine/base.py", line 1961, in _exec_single_context
    self.dialect.do_execute(
    ~~~~~~~~~~~~~~~~~~~~~~~^
        cursor, str_statement, effective_parameters, context
        ^^^^^^^^^^^^^^^^^^^^^^^^^^^^^^^^^^^^^^^^^^^^^^^^^^^^
    )
    ^
  File "/root/qr_checkout_latest/venv/lib/python3.13/site-packages/sqlalchemy/engine/default.py", line 944, in do_execute
    cursor.execute(statement, parameters)
    ~~~~~~~~~~~~~~^^^^^^^^^^^^^^^^^^^^^^^
sqlalchemy.exc.OperationalError: (sqlite3.OperationalError) no such table: ticket
[SQL: SELECT ticket.id AS ticket_id, ticket.name AS ticket_name, ticket.price AS ticket_price, ticket.user_id AS ticket_user_id 
FROM ticket 
WHERE ticket.user_id = ?]
[parameters: (1,)]
(Background on this error at: https://sqlalche.me/e/20/e3q8)
[2025-08-08 03:35:43,171] ERROR in app: Exception on / [GET]
Traceback (most recent call last):
  File "/root/qr_checkout_latest/venv/lib/python3.13/site-packages/sqlalchemy/engine/base.py", line 1961, in _exec_single_context
    self.dialect.do_execute(
    ~~~~~~~~~~~~~~~~~~~~~~~^
        cursor, str_statement, effective_parameters, context
        ^^^^^^^^^^^^^^^^^^^^^^^^^^^^^^^^^^^^^^^^^^^^^^^^^^^^
    )
    ^
  File "/root/qr_checkout_latest/venv/lib/python3.13/site-packages/sqlalchemy/engine/default.py", line 944, in do_execute
    cursor.execute(statement, parameters)
    ~~~~~~~~~~~~~~^^^^^^^^^^^^^^^^^^^^^^^
sqlite3.OperationalError: no such table: ticket

The above exception was the direct cause of the following exception:

Traceback (most recent call last):
  File "/root/qr_checkout_latest/venv/lib/python3.13/site-packages/flask/app.py", line 1511, in wsgi_app
    response = self.full_dispatch_request()
  File "/root/qr_checkout_latest/venv/lib/python3.13/site-packages/flask/app.py", line 919, in full_dispatch_request
    rv = self.handle_user_exception(e)
  File "/root/qr_checkout_latest/venv/lib/python3.13/site-packages/flask/app.py", line 917, in full_dispatch_request
    rv = self.dispatch_request()
  File "/root/qr_checkout_latest/venv/lib/python3.13/site-packages/flask/app.py", line 902, in dispatch_request
    return self.ensure_sync(self.view_functions[rule.endpoint])(**view_args)  # type: ignore[no-any-return]
           ~~~~~~~~~~~~~~~~~~~~~~~~~~~~~~~~~~~~~~~~~~~~~~~~~~~~^^^^^^^^^^^^^
  File "/root/qr_checkout_latest/venv/lib/python3.13/site-packages/flask_login/utils.py", line 290, in decorated_view
    return current_app.ensure_sync(func)(*args, **kwargs)
           ~~~~~~~~~~~~~~~~~~~~~~~~~~~~~^^^^^^^^^^^^^^^^^
  File "/root/qr_checkout_latest/app.py", line 95, in index
    # Pull this user's tickets
  File "/root/qr_checkout_latest/venv/lib/python3.13/site-packages/sqlalchemy/orm/query.py", line 2704, in all
    return self._iter().all()  # type: ignore
           ~~~~~~~~~~^^
  File "/root/qr_checkout_latest/venv/lib/python3.13/site-packages/sqlalchemy/orm/query.py", line 2857, in _iter
    result: Union[ScalarResult[_T], Result[_T]] = self.session.execute(
                                                  ~~~~~~~~~~~~~~~~~~~~^
        statement,
        ^^^^^^^^^^
        params,
        ^^^^^^^
        execution_options={"_sa_orm_load_options": self.load_options},
        ^^^^^^^^^^^^^^^^^^^^^^^^^^^^^^^^^^^^^^^^^^^^^^^^^^^^^^^^^^^^^^
    )
    ^
  File "/root/qr_checkout_latest/venv/lib/python3.13/site-packages/sqlalchemy/orm/session.py", line 2365, in execute
    return self._execute_internal(
           ~~~~~~~~~~~~~~~~~~~~~~^
        statement,
        ^^^^^^^^^^
    ...<4 lines>...
        _add_event=_add_event,
        ^^^^^^^^^^^^^^^^^^^^^^
    )
    ^
  File "/root/qr_checkout_latest/venv/lib/python3.13/site-packages/sqlalchemy/orm/session.py", line 2251, in _execute_internal
    result: Result[Any] = compile_state_cls.orm_execute_statement(
                          ~~~~~~~~~~~~~~~~~~~~~~~~~~~~~~~~~~~~~~~^
        self,
        ^^^^^
    ...<4 lines>...
        conn,
        ^^^^^
    )
    ^
  File "/root/qr_checkout_latest/venv/lib/python3.13/site-packages/sqlalchemy/orm/context.py", line 306, in orm_execute_statement
    result = conn.execute(
        statement, params or {}, execution_options=execution_options
    )
  File "/root/qr_checkout_latest/venv/lib/python3.13/site-packages/sqlalchemy/engine/base.py", line 1413, in execute
    return meth(
        self,
        distilled_parameters,
        execution_options or NO_OPTIONS,
    )
  File "/root/qr_checkout_latest/venv/lib/python3.13/site-packages/sqlalchemy/sql/elements.py", line 526, in _execute_on_connection
    return connection._execute_clauseelement(
           ~~~~~~~~~~~~~~~~~~~~~~~~~~~~~~~~~^
        self, distilled_params, execution_options
        ^^^^^^^^^^^^^^^^^^^^^^^^^^^^^^^^^^^^^^^^^
    )
    ^
  File "/root/qr_checkout_latest/venv/lib/python3.13/site-packages/sqlalchemy/engine/base.py", line 1635, in _execute_clauseelement
    ret = self._execute_context(
        dialect,
    ...<8 lines>...
        cache_hit=cache_hit,
    )
  File "/root/qr_checkout_latest/venv/lib/python3.13/site-packages/sqlalchemy/engine/base.py", line 1840, in _execute_context
    return self._exec_single_context(
           ~~~~~~~~~~~~~~~~~~~~~~~~~^
        dialect, context, statement, parameters
        ^^^^^^^^^^^^^^^^^^^^^^^^^^^^^^^^^^^^^^^
    )
    ^
  File "/root/qr_checkout_latest/venv/lib/python3.13/site-packages/sqlalchemy/engine/base.py", line 1980, in _exec_single_context
    self._handle_dbapi_exception(
    ~~~~~~~~~~~~~~~~~~~~~~~~~~~~^
        e, str_statement, effective_parameters, cursor, context
        ^^^^^^^^^^^^^^^^^^^^^^^^^^^^^^^^^^^^^^^^^^^^^^^^^^^^^^^
    )
    ^
  File "/root/qr_checkout_latest/venv/lib/python3.13/site-packages/sqlalchemy/engine/base.py", line 2349, in _handle_dbapi_exception
    raise sqlalchemy_exception.with_traceback(exc_info[2]) from e
  File "/root/qr_checkout_latest/venv/lib/python3.13/site-packages/sqlalchemy/engine/base.py", line 1961, in _exec_single_context
    self.dialect.do_execute(
    ~~~~~~~~~~~~~~~~~~~~~~~^
        cursor, str_statement, effective_parameters, context
        ^^^^^^^^^^^^^^^^^^^^^^^^^^^^^^^^^^^^^^^^^^^^^^^^^^^^
    )
    ^
  File "/root/qr_checkout_latest/venv/lib/python3.13/site-packages/sqlalchemy/engine/default.py", line 944, in do_execute
    cursor.execute(statement, parameters)
    ~~~~~~~~~~~~~~^^^^^^^^^^^^^^^^^^^^^^^
sqlalchemy.exc.OperationalError: (sqlite3.OperationalError) no such table: ticket
[SQL: SELECT ticket.id AS ticket_id, ticket.name AS ticket_name, ticket.price AS ticket_price, ticket.user_id AS ticket_user_id 
FROM ticket 
WHERE ticket.user_id = ?]
[parameters: (1,)]
(Background on this error at: https://sqlalche.me/e/20/e3q8)
